Workbook

Sheet Palinsesto
B2: =MATCH($F$2,Partite!E:E,0)-1 -> 1121 | C2: Data | D2: =TODAY() -> 46225 | F2: =TEXT(D2, "aaaa-mm-gg") -> 2026-07-22
C4: Campionato | D4: Giornata | E4: Data | F4: Ora | G4: Squadra | H4: V | I4: P | J4: S | K4: GF | L4: GS | M4: Diff. Reti | N4: Punti | O4: Pos. | P4: Forma1 | Q4: Forma2 | R4: Forma3 | S4: Forma4 | T4: Forma5 | U4: % | V4: Diff. | W4: 12+U 4,5 | X4: % | Y4: Multigol | Z4: % | AA4: Over 1,5 | AB4: % | AC4: Data | AD4: 0-2 | AE4: 1-3 | AF4: 2-5
B6: 1 | C6: =VLOOKUP($B$2+B6,Partite!$A$1:$Z$2322,2,FALSE) -> Champions League | D6: =VLOOKUP($B$2+B6,Partite!$A$1:$Z$2322,3,FALSE) -> 0 | E6: =VALUE(TEXT(AC6, "GG/MM/AAAA")) -> 46225 | F6: =VLOOKUP($B$2+B6,Partite!$A$1:$Z$2322,6,FALSE) -> 20:00 (19:00) | G6: =VLOOKUP($B$2+B6,Partite!$A$1:$Z$2322,7,FALSE) -> AC Omonia cy | H6: =IFERROR(VLOOKUP(G6,Classifica!$C$2:$R$131,3,FALSE),"") | I6: =IFERROR(VLOOKUP(G6,Classifica!$C$2:$R$131,4,FALSE),"") | J6: =IFERROR(VLOOKUP(G6,Classifica!$C$2:$R$131,5,FALSE),"") | K6: =IFERROR(VLOOKUP(G6,Classifica!$C$2:$R$131,6,FALSE),"") | L6: =IFERROR(VLOOKUP(G6,Classifica!$C$2:$R$131,7,FALSE),"") | M6: =IFERROR(VLOOKUP(G6,Classifica!$C$2:$R$131,8,FALSE),"") | N6: =IFERROR(VLOOKUP(G6,Classifica!$C$2:$R$131,9,FALSE),"") | O6: =IFERROR(VLOOKUP(G6,Classifica!$C$2:$R$131,16,FALSE),"") | P6: =IFERROR(MID(INDEX(Classifica!M:M, MATCH(G6, Classifica!C:C, 0)), 1, 1), "") | Q6: =IFERROR(MID(INDEX(Classifica!M:M, MATCH(G6, Classifica!C:C, 0)), 3, 1), "") | R6: =IFERROR(MID(INDEX(Classifica!M:M, MATCH(G6, Classifica!C:C, 0)), 5, 1), "") | S6: =IFERROR(MID(INDEX(Classifica!M:M, MATCH(G6, Classifica!C:C, 0)), 7, 1), "") | T6: =IFERROR(MID(INDEX(Classifica!M:M, MATCH(G6, Classifica!C:C, 0)), 9, 1), "") | U6: =IFERROR(IF(P6="","",COUNTIF(P6:T6,"W")*20+COUNTIF(P6:T6,"D")*7),"") | V6: =IFERROR(ABS(U6-U7),"") | W6: =COUNTIFS(Partite!AE:AE,1,Partite!Q:Q,Palinsesto!G6)+COUNTIFS(Partite!AE:AE,1,Partite!S:S,Palinsesto!G6) -> 0 | X6: =IFERROR(AVERAGE(IFERROR(INT(W6/(SUM(H6:J6))*100),""),IFERROR(INT(W7/(SUM(H7:J7))*100),"")),"") | Y6: =INDEX(AD$4:AF$4, MATCH(MAX(AD6:AF6), AD6:AF6, 0)) -> 0-2 | Z6: =IFERROR(INT((LARGE(AD6:AF6,1)/SUM(H6:J6))*100),"") | AA6: =COUNTIFS(Partite!AL:AL,1,Partite!Q:Q,Palinsesto!G6)+COUNTIFS(Partite!AL:AL,1,Partite!S:S,Palinsesto!G6) -> 0 | AB6: =IFERROR(INT(AVERAGE(AA6/(SUM(H6:J6))*100,(AA7/(SUM(H7:J7))*100))),"") | AC6: =VLOOKUP($B$2+B6,Partite!$A$1:$E$2322,5,FALSE) -> 2026-07-22 | AD6: =COUNTIFS(Partite!T:T,1,Partite!G:G,Palinsesto!G6)+COUNTIFS(Partite!W:W,1,Partite!I:I,Palinsesto!G6) -> 0 | AE6: =COUNTIFS(Partite!U:U,1,Partite!H:H,G6)+COUNTIFS(Partite!X:X,1,Partite!J:J,G6) -> 0 | AF6: =COUNTIFS(Partite!V:V,1,Partite!I:I,G6)+COUNTIFS(Partite!Y:Y,1,Partite!K:K,G6) -> 0
G7: =VLOOKUP($B$2+B6,Partite!$A$1:$Z$2322,9,FALSE) -> kz FC Kairat | H7: =IFERROR(VLOOKUP(G7,Classifica!$C$2:$R$131,3,FALSE),"") | I7: =IFERROR(VLOOKUP(G7,Classifica!$C$2:$R$131,4,FALSE),"") | J7: =IFERROR(VLOOKUP(G7,Classifica!$C$2:$R$131,5,FALSE),"") | K7: =IFERROR(VLOOKUP(G7,Classifica!$C$2:$R$131,6,FALSE),"") | L7: =IFERROR(VLOOKUP(G7,Classifica!$C$2:$R$131,7,FALSE),"") | M7: =IFERROR(VLOOKUP(G7,Classifica!$C$2:$R$131,8,FALSE),"") | N7: =IFERROR(VLOOKUP(G7,Classifica!$C$2:$R$131,9,FALSE),"") | O7: =IFERROR(VLOOKUP(G7,Classifica!$C$2:$R$131,16,FALSE),"") | P7: =IFERROR(MID(INDEX(Classifica!M:M, MATCH(G7, Classifica!C:C, 0)), 1, 1), "") | Q7: =IFERROR(MID(INDEX(Classifica!M:M, MATCH(G7, Classifica!C:C, 0)), 3, 1), "") | R7: =IFERROR(MID(INDEX(Classifica!M:M, MATCH(G7, Classifica!C:C, 0)), 5, 1), "") | S7: =IFERROR(MID(INDEX(Classifica!M:M, MATCH(G7, Classifica!C:C, 0)), 7, 1), "") | T7: =IFERROR(MID(INDEX(Classifica!M:M, MATCH(G7, Classifica!C:C, 0)), 9, 1), "") | U7: =IFERROR(IF(P7="","",COUNTIF(P7:T7,"W")*20+COUNTIF(P7:T7,"D")*7),"") | W7: =COUNTIFS(Partite!AE:AE,1,Partite!Q:Q,Palinsesto!G7)+COUNTIFS(Partite!AE:AE,1,Partite!S:S,Palinsesto!G7) -> 0 | Y7: =INDEX(AD$4:AF$4, MATCH(MAX(AD7:AF7), AD7:AF7, 0)) -> 0-2 | Z7: =IFERROR(INT((LARGE(AD7:AF7,1)/SUM(H7:J7))*100),"") | AA7: =COUNTIFS(Partite!AL:AL,1,Partite!Q:Q,Palinsesto!G7)+COUNTIFS(Partite!AL:AL,1,Partite!S:S,Palinsesto!G7) -> 0 | AD7: =COUNTIFS(Partite!T:T,1,Partite!G:G,Palinsesto!G7)+COUNTIFS(Partite!W:W,1,Partite!I:I,Palinsesto!G7) -> 1 | AE7: =COUNTIFS(Partite!U:U,1,Partite!H:H,G7)+COUNTIFS(Partite!X:X,1,Partite!J:J,G7) -> 0 | AF7: =COUNTIFS(Partite!V:V,1,Partite!I:I,G7)+COUNTIFS(Partite!Y:Y,1,Partite!K:K,G7) -> 0
B9: =B6+1 -> 2 | C9: =VLOOKUP($B$2+B9,Partite!$A$1:$Z$2322,2,FALSE) -> Champions League | D9: =VLOOKUP($B$2+B9,Partite!$A$1:$Z$2322,3,FALSE) -> 0 | E9: =VALUE(TEXT(AC9, "GG/MM/AAAA")) -> 46225 | F9: =VLOOKUP($B$2+B9,Partite!$A$1:$Z$2322,6,FALSE) -> 20:30 (19:30) | G9: =VLOOKUP($B$2+B9,Partite!$A$1:$Z$2322,7,FALSE) -> Levski Sofia bg | H9: =IFERROR(VLOOKUP(G9,Classifica!$C$2:$R$131,3,FALSE),"") | I9: =IFERROR(VLOOKUP(G9,Classifica!$C$2:$R$131,4,FALSE),"") | J9: =IFERROR(VLOOKUP(G9,Classifica!$C$2:$R$131,5,FALSE),"") | K9: =IFERROR(VLOOKUP(G9,Classifica!$C$2:$R$131,6,FALSE),"") | L9: =IFERROR(VLOOKUP(G9,Classifica!$C$2:$R$131,7,FALSE),"") | M9: =IFERROR(VLOOKUP(G9,Classifica!$C$2:$R$131,8,FALSE),"") | N9: =IFERROR(VLOOKUP(G9,Classifica!$C$2:$R$131,9,FALSE),"") | O9: =IFERROR(VLOOKUP(G9,Classifica!$C$2:$R$131,16,FALSE),"") | P9: =IFERROR(MID(INDEX(Classifica!M:M, MATCH(G9, Classifica!C:C, 0)), 1, 1), "") | Q9: =IFERROR(MID(INDEX(Classifica!M:M, MATCH(G9, Classifica!C:C, 0)), 3, 1), "") | R9: =IFERROR(MID(INDEX(Classifica!M:M, MATCH(G9, Classifica!C:C, 0)), 5, 1), "") | S9: =IFERROR(MID(INDEX(Classifica!M:M, MATCH(G9, Classifica!C:C, 0)), 7, 1), "") | T9: =IFERROR(MID(INDEX(Classifica!M:M, MATCH(G9, Classifica!C:C, 0)), 9, 1), "") | U9: =IFERROR(IF(P9="","",COUNTIF(P9:T9,"W")*20+COUNTIF(P9:T9,"D")*7),"") | V9: =IFERROR(ABS(U9-U10),"") | W9: =COUNTIFS(Partite!AE:AE,1,Partite!Q:Q,Palinsesto!G9)+COUNTIFS(Partite!AE:AE,1,Partite!S:S,Palinsesto!G9) -> 0 | X9: =IFERROR(AVERAGE(IFERROR(INT(W9/(SUM(H9:J9))*100),""),IFERROR(INT(W10/(SUM(H10:J10))*100),"")),"") | Y9: =INDEX(AD$4:AF$4, MATCH(MAX(AD9:AF9), AD9:AF9, 0)) -> 0-2 | Z9: =IFERROR(INT((LARGE(AD9:AF9,1)/SUM(H9:J9))*100),"") | AA9: =COUNTIFS(Partite!AL:AL,1,Partite!Q:Q,Palinsesto!G9)+COUNTIFS(Partite!AL:AL,1,Partite!S:S,Palinsesto!G9) -> 0 | AB9: =IFERROR(INT(AVERAGE(AA9/(SUM(H9:J9))*100,(AA10/(SUM(H10:J10))*100))),"") | AC9: =VLOOKUP($B$2+B9,Partite!$A$1:$E$2322,5,FALSE) -> 2026-07-22 | AD9: =COUNTIFS(Partite!T:T,1,Partite!G:G,Palinsesto!G9)+COUNTIFS(Partite!W:W,1,Partite!I:I,Palinsesto!G9) -> 0 | AE9: =COUNTIFS(Partite!U:U,1,Partite!H:H,G9)+COUNTIFS(Partite!X:X,1,Partite!J:J,G9) -> 0 | AF9: =COUNTIFS(Partite!V:V,1,Partite!I:I,G9)+COUNTIFS(Partite!Y:Y,1,Partite!K:K,G9) -> 0
G10: =VLOOKUP($B$2+B9,Partite!$A$1:$Z$2322,9,FALSE) -> ro CS U Craiova | H10: =IFERROR(VLOOKUP(G10,Classifica!$C$2:$R$131,3,FALSE),"") | I10: =IFERROR(VLOOKUP(G10,Classifica!$C$2:$R$131,4,FALSE),"") | J10: =IFERROR(VLOOKUP(G10,Classifica!$C$2:$R$131,5,FALSE),"") | K10: =IFERROR(VLOOKUP(G10,Classifica!$C$2:$R$131,6,FALSE),"") | L10: =IFERROR(VLOOKUP(G10,Classifica!$C$2:$R$131,7,FALSE),"") | M10: =IFERROR(VLOOKUP(G10,Classifica!$C$2:$R$131,8,FALSE),"") | N10: =IFERROR(VLOOKUP(G10,Classifica!$C$2:$R$131,9,FALSE),"") | O10: =IFERROR(VLOOKUP(G10,Classifica!$C$2:$R$131,16,FALSE),"") | P10: =IFERROR(MID(INDEX(Classifica!M:M, MATCH(G10, Classifica!C:C, 0)), 1, 1), "") | Q10: =IFERROR(MID(INDEX(Classifica!M:M, MATCH(G10, Classifica!C:C, 0)), 3, 1), "") | R10: =IFERROR(MID(INDEX(Classifica!M:M, MATCH(G10, Classifica!C:C, 0)), 5, 1), "") | S10: =IFERROR(MID(INDEX(Classifica!M:M, MATCH(G10, Classifica!C:C, 0)), 7, 1), "") | T10: =IFERROR(MID(INDEX(Classifica!M:M, MATCH(G10, Classifica!C:C, 0)), 9, 1), "") | U10: =IFERROR(IF(P10="","",COUNTIF(P10:T10,"W")*20+COUNTIF(P10:T10,"D")*7),"") | W10: =COUNTIFS(Partite!AE:AE,1,Partite!Q:Q,Palinsesto!G10)+COUNTIFS(Partite!AE:AE,1,Partite!S:S,Palinsesto!G10) -> 0 | Y10: =INDEX(AD$4:AF$4, MATCH(MAX(AD10:AF10), AD10:AF10, 0)) -> 0-2 | Z10: =IFERROR(INT((LARGE(AD10:AF10,1)/SUM(H10:J10))*100),"") | AA10: =COUNTIFS(Partite!AL:AL,1,Partite!Q:Q,Palinsesto!G10)+COUNTIFS(Partite!AL:AL,1,Partite!S:S,Palinsesto!G10) -> 0 | AD10: =COUNTIFS(Partite!T:T,1,Partite!G:G,Palinsesto!G10)+COUNTIFS(Partite!W:W,1,Partite!I:I,Palinsesto!G10) -> 0 | AE10: =COUNTIFS(Partite!U:U,1,Partite!H:H,G10)+COUNTIFS(Partite!X:X,1,Partite!J:J,G10) -> 0 | AF10: =COUNTIFS(Partite!V:V,1,Partite!I:I,G10)+COUNTIFS(Partite!Y:Y,1,Partite!K:K,G10) -> 0
B12: =B9+1 -> 3 | C12: =VLOOKUP($B$2+B12,Partite!$A$1:$Z$2322,2,FALSE) -> Champions League | D12: =VLOOKUP($B$2+B12,Partite!$A$1:$Z$2322,3,FALSE) -> 0 | E12: =VALUE(TEXT(AC12, "GG/MM/AAAA")) -> 46225 | F12: =VLOOKUP($B$2+B12,Partite!$A$1:$Z$2322,6,FALSE) -> 21:00 | G12: =VLOOKUP($B$2+B12,Partite!$A$1:$Z$2322,7,FALSE) -> FK Egnatia al | H12: =IFERROR(VLOOKUP(G12,Classifica!$C$2:$R$131,3,FALSE),"") | I12: =IFERROR(VLOOKUP(G12,Classifica!$C$2:$R$131,4,FALSE),"") | J12: =IFERROR(VLOOKUP(G12,Classifica!$C$2:$R$131,5,FALSE),"") | K12: =IFERROR(VLOOKUP(G12,Classifica!$C$2:$R$131,6,FALSE),"") | L12: =IFERROR(VLOOKUP(G12,Classifica!$C$2:$R$131,7,FALSE),"") | M12: =IFERROR(VLOOKUP(G12,Classifica!$C$2:$R$131,8,FALSE),"") | N12: =IFERROR(VLOOKUP(G12,Classifica!$C$2:$R$131,9,FALSE),"") | O12: =IFERROR(VLOOKUP(G12,Classifica!$C$2:$R$131,16,FALSE),"") | P12: =IFERROR(MID(INDEX(Classifica!M:M, MATCH(G12, Classifica!C:C, 0)), 1, 1), "") | Q12: =IFERROR(MID(INDEX(Classifica!M:M, MATCH(G12, Classifica!C:C, 0)), 3, 1), "") | R12: =IFERROR(MID(INDEX(Classifica!M:M, MATCH(G12, Classifica!C:C, 0)), 5, 1), "") | S12: =IFERROR(MID(INDEX(Classifica!M:M, MATCH(G12, Classifica!C:C, 0)), 7, 1), "") | T12: =IFERROR(MID(INDEX(Classifica!M:M, MATCH(G12, Classifica!C:C, 0)), 9, 1), "") | U12: =IFERROR(IF(P12="","",COUNTIF(P12:T12,"W")*20+COUNTIF(P12:T12,"D")*7),"") | V12: =IFERROR(ABS(U12-U13),"") | W12: =COUNTIFS(Partite!AE:AE,1,Partite!Q:Q,Palinsesto!G12)+COUNTIFS(Partite!AE:AE,1,Partite!S:S,Palinsesto!G12) -> 0 | X12: =IFERROR(AVERAGE(IFERROR(INT(W12/(SUM(H12:J12))*100),""),IFERROR(INT(W13/(SUM(H13:J13))*100),"")),"") | Y12: =INDEX(AD$4:AF$4, MATCH(MAX(AD12:AF12), AD12:AF12, 0)) -> 0-2 | Z12: =IFERROR(INT((LARGE(AD12:AF12,1)/SUM(H12:J12))*100),"") | AA12: =COUNTIFS(Partite!AL:AL,1,Partite!Q:Q,Palinsesto!G12)+COUNTIFS(Partite!AL:AL,1,Partite!S:S,Palinsesto!G12) -> 0 | AB12: =IFERROR(INT(AVERAGE(AA12/(SUM(H12:J12))*100,(AA13/(SUM(H13:J13))*100))),"") | AC12: =VLOOKUP($B$2+B12,Partite!$A$1:$E$2322,5,FALSE) -> 2026-07-22 | AD12: =COUNTIFS(Partite!T:T,1,Partite!G:G,Palinsesto!G12)+COUNTIFS(Partite!W:W,1,Partite!I:I,Palinsesto!G12) -> 0 | AE12: =COUNTIFS(Partite!U:U,1,Partite!H:H,G12)+COUNTIFS(Partite!X:X,1,Partite!J:J,G12) -> 0 | AF12: =COUNTIFS(Partite!V:V,1,Partite!I:I,G12)+COUNTIFS(Partite!Y:Y,1,Partite!K:K,G12) -> 0
G13: =VLOOKUP($B$2+B12,Partite!$A$1:$Z$2322,9,FALSE) -> si NK Celje | H13: =IFERROR(VLOOKUP(G13,Classifica!$C$2:$R$131,3,FALSE),"") | I13: =IFERROR(VLOOKUP(G13,Classifica!$C$2:$R$131,4,FALSE),"") | J13: =IFERROR(VLOOKUP(G13,Classifica!$C$2:$R$131,5,FALSE),"") | K13: =IFERROR(VLOOKUP(G13,Classifica!$C$2:$R$131,6,FALSE),"") | L13: =IFERROR(VLOOKUP(G13,Classifica!$C$2:$R$131,7,FALSE),"") | M13: =IFERROR(VLOOKUP(G13,Classifica!$C$2:$R$131,8,FALSE),"") | N13: =IFERROR(VLOOKUP(G13,Classifica!$C$2:$R$131,9,FALSE),"") | O13: =IFERROR(VLOOKUP(G13,Classifica!$C$2:$R$131,16,FALSE),"") | P13: =IFERROR(MID(INDEX(Classifica!M:M, MATCH(G13, Classifica!C:C, 0)), 1, 1), "") | Q13: =IFERROR(MID(INDEX(Classifica!M:M, MATCH(G13, Classifica!C:C, 0)), 3, 1), "") | R13: =IFERROR(MID(INDEX(Classifica!M:M, MATCH(G13, Classifica!C:C, 0)), 5, 1), "") | S13: =IFERROR(MID(INDEX(Classifica!M:M, MATCH(G13, Classifica!C:C, 0)), 7, 1), "") | T13: =IFERROR(MID(INDEX(Classifica!M:M, MATCH(G13, Classifica!C:C, 0)), 9, 1), "") | U13: =IFERROR(IF(P13="","",COUNTIF(P13:T13,"W")*20+COUNTIF(P13:T13,"D")*7),"") | W13: =COUNTIFS(Partite!AE:AE,1,Partite!Q:Q,Palinsesto!G13)+COUNTIFS(Partite!AE:AE,1,Partite!S:S,Palinsesto!G13) -> 0 | Y13: =INDEX(AD$4:AF$4, MATCH(MAX(AD13:AF13), AD13:AF13, 0)) -> 0-2 | Z13: =IFERROR(INT((LARGE(AD13:AF13,1)/SUM(H13:J13))*100),"") | AA13: =COUNTIFS(Partite!AL:AL,1,Partite!Q:Q,Palinsesto!G13)+COUNTIFS(Partite!AL:AL,1,Partite!S:S,Palinsesto!G13) -> 0 | AD13: =COUNTIFS(Partite!T:T,1,Partite!G:G,Palinsesto!G13)+COUNTIFS(Partite!W:W,1,Partite!I:I,Palinsesto!G13) -> 0 | AE13: =COUNTIFS(Partite!U:U,1,Partite!H:H,G13)+COUNTIFS(Partite!X:X,1,Partite!J:J,G13) -> 0 | AF13: =COUNTIFS(Partite!V:V,1,Partite!I:I,G13)+COUNTIFS(Partite!Y:Y,1,Partite!K:K,G13) -> 0
B15: =B12+1 -> 4 | C15: =VLOOKUP($B$2+B15,Partite!$A$1:$Z$2322,2,FALSE) -> Eliteserien | D15: =VLOOKUP($B$2+B15,Partite!$A$1:$Z$2322,3,FALSE) -> 2 | E15: =VALUE(TEXT(AC15, "GG/MM/AAAA")) -> 46225 | F15: =VLOOKUP($B$2+B15,Partite!$A$1:$Z$2322,6,FALSE) -> 19:00 | G15: =VLOOKUP($B$2+B15,Partite!$A$1:$Z$2322,7,FALSE) -> Bodø/Glimt | H15: =IFERROR(VLOOKUP(G15,Classifica!$C$2:$R$131,3,FALSE),"") -> 9 | I15: =IFERROR(VLOOKUP(G15,Classifica!$C$2:$R$131,4,FALSE),"") -> 2 | J15: =IFERROR(VLOOKUP(G15,Classifica!$C$2:$R$131,5,FALSE),"") -> 2 | K15: =IFERROR(VLOOKUP(G15,Classifica!$C$2:$R$131,6,FALSE),"") -> 31 | L15: =IFERROR(VLOOKUP(G15,Classifica!$C$2:$R$131,7,FALSE),"") -> 11 | M15: =IFERROR(VLOOKUP(G15,Classifica!$C$2:$R$131,8,FALSE),"") -> 20 | N15: =IFERROR(VLOOKUP(G15,Classifica!$C$2:$R$131,9,FALSE),"") -> 29 | O15: =IFERROR(VLOOKUP(G15,Classifica!$C$2:$R$131,16,FALSE),"") -> 3 | P15: =IFERROR(MID(INDEX(Classifica!M:M, MATCH(G15, Classifica!C:C, 0)), 1, 1), "") -> W | Q15: =IFERROR(MID(INDEX(Classifica!M:M, MATCH(G15, Classifica!C:C, 0)), 3, 1), "") -> W | R15: =IFERROR(MID(INDEX(Classifica!M:M, MATCH(G15, Classifica!C:C, 0)), 5, 1), "") -> D | S15: =IFERROR(MID(INDEX(Classifica!M:M, MATCH(G15, Classifica!C:C, 0)), 7, 1), "") -> W | T15: =IFERROR(MID(INDEX(Classifica!M:M, MATCH(G15, Classifica!C:C, 0)), 9, 1), "") -> W | U15: =IFERROR(IF(P15="","",COUNTIF(P15:T15,"W")*20+COUNTIF(P15:T15,"D")*7),"") -> 87 | V15: =IFERROR(ABS(U15-U16),"") -> 53 | W15: =COUNTIFS(Partite!AE:AE,1,Partite!Q:Q,Palinsesto!G15)+COUNTIFS(Partite!AE:AE,1,Partite!S:S,Palinsesto!G15) -> 0 | X15: =IFERROR(AVERAGE(IFERROR(INT(W15/(SUM(H15:J15))*100),""),IFERROR(INT(W16/(SUM(H16:J16))*100),"")),"") -> 0 | Y15: =INDEX(AD$4:AF$4, MATCH(MAX(AD15:AF15), AD15:AF15, 0)) -> 0-2 | Z15: =IFERROR(INT((LARGE(AD15:AF15,1)/SUM(H15:J15))*100),"") -> 53 | AA15: =COUNTIFS(Partite!AL:AL,1,Partite!Q:Q,Palinsesto!G15)+COUNTIFS(Partite!AL:AL,1,Partite!S:S,Palinsesto!G15) -> 0 | AB15: =IFERROR(INT(AVERAGE(AA15/(SUM(H15:J15))*100,(AA16/(SUM(H16:J16))*100))),"") -> 0 | AC15: =VLOOKUP($B$2+B15,Partite!$A$1:$E$2322,5,FALSE) -> 2026-07-22 | AD15: =COUNTIFS(Partite!T:T,1,Partite!G:G,Palinsesto!G15)+COUNTIFS(Partite!W:W,1,Partite!I:I,Palinsesto!G15) -> 7 | AE15: =COUNTIFS(Partite!U:U,1,Partite!H:H,G15)+COUNTIFS(Partite!X:X,1,Partite!J:J,G15) -> 0 | AF15: =COUNTIFS(Partite!V:V,1,Partite!I:I,G15)+COUNTIFS(Partite!Y:Y,1,Partite!K:K,G15) -> 2
G16: =VLOOKUP($B$2+B15,Partite!$A$1:$Z$2322,9,FALSE) -> HamKam | H16: =IFERROR(VLOOKUP(G16,Classifica!$C$2:$R$131,3,FALSE),"") -> 5 | I16: =IFERROR(VLOOKUP(G16,Classifica!$C$2:$R$131,4,FALSE),"") -> 3 | J16: =IFERROR(VLOOKUP(G16,Classifica!$C$2:$R$131,5,FALSE),"") -> 4 | K16: =IFERROR(VLOOKUP(G16,Classifica!$C$2:$R$131,6,FALSE),"") -> 20 | L16: =IFERROR(VLOOKUP(G16,Classifica!$C$2:$R$131,7,FALSE),"") -> 22 | M16: =IFERROR(VLOOKUP(G16,Classifica!$C$2:$R$131,8,FALSE),"") -> -2 | N16: =IFERROR(VLOOKUP(G16,Classifica!$C$2:$R$131,9,FALSE),"") -> 18 | O16: =IFERROR(VLOOKUP(G16,Classifica!$C$2:$R$131,16,FALSE),"") -> 7 | P16: =IFERROR(MID(INDEX(Classifica!M:M, MATCH(G16, Classifica!C:C, 0)), 1, 1), "") -> L | Q16: =IFERROR(MID(INDEX(Classifica!M:M, MATCH(G16, Classifica!C:C, 0)), 3, 1), "") -> W | R16: =IFERROR(MID(INDEX(Classifica!M:M, MATCH(G16, Classifica!C:C, 0)), 5, 1), "") -> D | S16: =IFERROR(MID(INDEX(Classifica!M:M, MATCH(G16, Classifica!C:C, 0)), 7, 1), "") -> D | T16: =IFERROR(MID(INDEX(Classifica!M:M, MATCH(G16, Classifica!C:C, 0)), 9, 1), "") -> L | U16: =IFERROR(IF(P16="","",COUNTIF(P16:T16,"W")*20+COUNTIF(P16:T16,"D")*7),"") -> 34 | W16: =COUNTIFS(Partite!AE:AE,1,Partite!Q:Q,Palinsesto!G16)+COUNTIFS(Partite!AE:AE,1,Partite!S:S,Palinsesto!G16) -> 0 | Y16: =INDEX(AD$4:AF$4, MATCH(MAX(AD16:AF16), AD16:AF16, 0)) -> 0-2 | Z16: =IFERROR(INT((LARGE(AD16:AF16,1)/SUM(H16:J16))*100),"") -> 91 | AA16: =COUNTIFS(Partite!AL:AL,1,Partite!Q:Q,Palinsesto!G16)+COUNTIFS(Partite!AL:AL,1,Partite!S:S,Palinsesto!G16) -> 0 | AD16: =COUNTIFS(Partite!T:T,1,Partite!G:G,Palinsesto!G16)+COUNTIFS(Partite!W:W,1,Partite!I:I,Palinsesto!G16) -> 11 | AE16: =COUNTIFS(Partite!U:U,1,Partite!H:H,G16)+COUNTIFS(Partite!X:X,1,Partite!J:J,G16) -> 0 | AF16: =COUNTIFS(Partite!V:V,1,Partite!I:I,G16)+COUNTIFS(Partite!Y:Y,1,Partite!K:K,G16) -> 4
B18: =B15+1 -> 5 | C18: =VLOOKUP($B$2+B18,Partite!$A$1:$Z$2322,2,FALSE) -> Eliteserien | D18: =VLOOKUP($B$2+B18,Partite!$A$1:$Z$2322,3,FALSE) -> 11 | E18: =VALUE(TEXT(AC18, "GG/MM/AAAA")) -> 46225 | F18: =VLOOKUP($B$2+B18,Partite!$A$1:$Z$2322,6,FALSE) -> 19:00 | G18: =VLOOKUP($B$2+B18,Partite!$A$1:$Z$2322,7,FALSE) -> Lillestrøm | H18: =IFERROR(VLOOKUP(G18,Classifica!$C$2:$R$131,3,FALSE),"") -> 8 | I18: =IFERROR(VLOOKUP(G18,Classifica!$C$2:$R$131,4,FALSE),"") -> 1 | J18: =IFERROR(VLOOKUP(G18,Classifica!$C$2:$R$131,5,FALSE),"") -> 4 | K18: =IFERROR(VLOOKUP(G18,Classifica!$C$2:$R$131,6,FALSE),"") -> 21 | L18: =IFERROR(VLOOKUP(G18,Classifica!$C$2:$R$131,7,FALSE),"") -> 12 | M18: =IFERROR(VLOOKUP(G18,Classifica!$C$2:$R$131,8,FALSE),"") -> 9 | N18: =IFERROR(VLOOKUP(G18,Classifica!$C$2:$R$131,9,FALSE),"") -> 25 | O18: =IFERROR(VLOOKUP(G18,Classifica!$C$2:$R$131,16,FALSE),"") -> 4 | P18: =IFERROR(MID(INDEX(Classifica!M:M, MATCH(G18, Classifica!C:C, 0)), 1, 1), "") -> W | Q18: =IFERROR(MID(INDEX(Classifica!M:M, MATCH(G18, Classifica!C:C, 0)), 3, 1), "") -> L | R18: =IFERROR(MID(INDEX(Classifica!M:M, MATCH(G18, Classifica!C:C, 0)), 5, 1), "") -> L | S18: =IFERROR(MID(INDEX(Classifica!M:M, MATCH(G18, Classifica!C:C, 0)), 7, 1), "") -> W | T18: =IFERROR(MID(INDEX(Classifica!M:M, MATCH(G18, Classifica!C:C, 0)), 9, 1), "") -> W | U18: =IFERROR(IF(P18="","",COUNTIF(P18:T18,"W")*20+COUNTIF(P18:T18,"D")*7),"") -> 60 | V18: =IFERROR(ABS(U18-U19),"") -> 20 | W18: =COUNTIFS(Partite!AE:AE,1,Partite!Q:Q,Palinsesto!G18)+COUNTIFS(Partite!AE:AE,1,Partite!S:S,Palinsesto!G18) -> 0 | X18: =IFERROR(AVERAGE(IFERROR(INT(W18/(SUM(H18:J18))*100),""),IFERROR(INT(W19/(SUM(H19:J19))*100),"")),"") -> 0 | Y18: =INDEX(AD$4:AF$4, MATCH(MAX(AD18:AF18), AD18:AF18, 0)) -> 0-2 | Z18: =IFERROR(INT((LARGE(AD18:AF18,1)/SUM(H18:J18))*100),"") -> 69 | AA18: =COUNTIFS(Partite!AL:AL,1,Partite!Q:Q,Palinsesto!G18)+COUNTIFS(Partite!AL:AL,1,Partite!S:S,Palinsesto!G18) -> 0 | AB18: =IFERROR(INT(AVERAGE(AA18/(SUM(H18:J18))*100,(AA19/(SUM(H19:J19))*100))),"") -> 0 | AC18: =VLOOKUP($B$2+B18,Partite!$A$1:$E$2322,5,FALSE) -> 2026-07-22 | AD18: =COUNTIFS(Partite!T:T,1,Partite!G:G,Palinsesto!G18)+COUNTIFS(Partite!W:W,1,Partite!I:I,Palinsesto!G18) -> 9 | AE18: =COUNTIFS(Partite!U:U,1,Partite!H:H,G18)+COUNTIFS(Partite!X:X,1,Partite!J:J,G18) -> 0 | AF18: =COUNTIFS(Partite!V:V,1,Partite!I:I,G18)+COUNTIFS(Partite!Y:Y,1,Partite!K:K,G18) -> 2
G19: =VLOOKUP($B$2+B18,Partite!$A$1:$Z$2322,9,FALSE) -> Viking | H19: =IFERROR(VLOOKUP(G19,Classifica!$C$2:$R$131,3,FALSE),"") -> 10 | I19: =IFERROR(VLOOKUP(G19,Classifica!$C$2:$R$131,4,FALSE),"") -> 0 | J19: =IFERROR(VLOOKUP(G19,Classifica!$C$2:$R$131,5,FALSE),"") -> 2 | K19: =IFERROR(VLOOKUP(G19,Classifica!$C$2:$R$131,6,FALSE),"") -> 31 | L19: =IFERROR(VLOOKUP(G19,Classifica!$C$2:$R$131,7,FALSE),"") -> 12 | M19: =IFERROR(VLOOKUP(G19,Classifica!$C$2:$R$131,8,FALSE),"") -> 19 | N19: =IFERROR(VLOOKUP(G19,Classifica!$C$2:$R$131,9,FALSE),"") -> 30 | O19: =IFERROR(VLOOKUP(G19,Classifica!$C$2:$R$131,16,FALSE),"") -> 2 | P19: =IFERROR(MID(INDEX(Classifica!M:M, MATCH(G19, Classifica!C:C, 0)), 1, 1), "") -> W | Q19: =IFERROR(MID(INDEX(Classifica!M:M, MATCH(G19, Classifica!C:C, 0)), 3, 1), "") -> W | R19: =IFERROR(MID(INDEX(Classifica!M:M, MATCH(G19, Classifica!C:C, 0)), 5, 1), "") -> W | S19: =IFERROR(MID(INDEX(Classifica!M:M, MATCH(G19, Classifica!C:C, 0)), 7, 1), "") -> L | T19: =IFERROR(MID(INDEX(Classifica!M:M, MATCH(G19, Classifica!C:C, 0)), 9, 1), "") -> W | U19: =IFERROR(IF(P19="","",COUNTIF(P19:T19,"W")*20+COUNTIF(P19:T19,"D")*7),"") -> 80 | W19: =COUNTIFS(Partite!AE:AE,1,Partite!Q:Q,Palinsesto!G19)+COUNTIFS(Partite!AE:AE,1,Partite!S:S,Palinsesto!G19) -> 0 | Y19: =INDEX(AD$4:AF$4, MATCH(MAX(AD19:AF19), AD19:AF19, 0)) -> 0-2 | Z19: =IFERROR(INT((LARGE(AD19:AF19,1)/SUM(H19:J19))*100),"") -> 58 | AA19: =COUNTIFS(Partite!AL:AL,1,Partite!Q:Q,Palinsesto!G19)+COUNTIFS(Partite!AL:AL,1,Partite!S:S,Palinsesto!G19) -> 0 | AD19: =COUNTIFS(Partite!T:T,1,Partite!G:G,Palinsesto!G19)+COUNTIFS(Partite!W:W,1,Partite!I:I,Palinsesto!G19) -> 7 | AE19: =COUNTIFS(Partite!U:U,1,Partite!H:H,G19)+COUNTIFS(Partite!X:X,1,Partite!J:J,G19) -> 0 | AF19: =COUNTIFS(Partite!V:V,1,Partite!I:I,G19)+COUNTIFS(Partite!Y:Y,1,Partite!K:K,G19) -> 1
B21: =B18+1 -> 6 | C21: =VLOOKUP($B$2+B21,Partite!$A$1:$Z$2322,2,FALSE) -> K League 1 | D21: =VLOOKUP($B$2+B21,Partite!$A$1:$Z$2322,3,FALSE) -> 19 | E21: =VALUE(TEXT(AC21, "GG/MM/AAAA")) -> 46225 | F21: =VLOOKUP($B$2+B21,Partite!$A$1:$Z$2322,6,FALSE) -> 19:30 (12:30) | G21: =VLOOKUP($B$2+B21,Partite!$A$1:$Z$2322,7,FALSE) -> FC Seoul | H21: =IFERROR(VLOOKUP(G21,Classifica!$C$2:$R$131,3,FALSE),"") -> 11 | I21: =IFERROR(VLOOKUP(G21,Classifica!$C$2:$R$131,4,FALSE),"") -> 3 | J21: =IFERROR(VLOOKUP(G21,Classifica!$C$2:$R$131,5,FALSE),"") -> 3 | K21: =IFERROR(VLOOKUP(G21,Classifica!$C$2:$R$131,6,FALSE),"") -> 28 | L21: =IFERROR(VLOOKUP(G21,Classifica!$C$2:$R$131,7,FALSE),"") -> 12 | M21: =IFERROR(VLOOKUP(G21,Classifica!$C$2:$R$131,8,FALSE),"") -> 16 | N21: =IFERROR(VLOOKUP(G21,Classifica!$C$2:$R$131,9,FALSE),"") -> 36 | O21: =IFERROR(VLOOKUP(G21,Classifica!$C$2:$R$131,16,FALSE),"") -> 1 | P21: =IFERROR(MID(INDEX(Classifica!M:M, MATCH(G21, Classifica!C:C, 0)), 1, 1), "") -> L | Q21: =IFERROR(MID(INDEX(Classifica!M:M, MATCH(G21, Classifica!C:C, 0)), 3, 1), "") -> W | R21: =IFERROR(MID(INDEX(Classifica!M:M, MATCH(G21, Classifica!C:C, 0)), 5, 1), "") -> W | S21: =IFERROR(MID(INDEX(Classifica!M:M, MATCH(G21, Classifica!C:C, 0)), 7, 1), "") -> W | T21: =IFERROR(MID(INDEX(Classifica!M:M, MATCH(G21, Classifica!C:C, 0)), 9, 1), "") -> D | U21: =IFERROR(IF(P21="","",COUNTIF(P21:T21,"W")*20+COUNTIF(P21:T21,"D")*7),"") -> 67 | V21: =IFERROR(ABS(U21-U22),"") -> 7 | W21: =COUNTIFS(Partite!AE:AE,1,Partite!Q:Q,Palinsesto!G21)+COUNTIFS(Partite!AE:AE,1,Partite!S:S,Palinsesto!G21) -> 0 | X21: =IFERROR(AVERAGE(IFERROR(INT(W21/(SUM(H21:J21))*100),""),IFERROR(INT(W22/(SUM(H22:J22))*100),"")),"") -> 0 | Y21: =INDEX(AD$4:AF$4, MATCH(MAX(AD21:AF21), AD21:AF21, 0)) -> 0-2 | Z21: =IFERROR(INT((LARGE(AD21:AF21,1)/SUM(H21:J21))*100),"") -> 82 | AA21: =COUNTIFS(Partite!AL:AL,1,Partite!Q:Q,Palinsesto!G21)+COUNTIFS(Partite!AL:AL,1,Partite!S:S,Palinsesto!G21) -> 0 | AB21: =IFERROR(INT(AVERAGE(AA21/(SUM(H21:J21))*100,(AA22/(SUM(H22:J22))*100))),"") -> 0 | AC21: =VLOOKUP($B$2+B21,Partite!$A$1:$E$2322,5,FALSE) -> 2026-07-22 | AD21: =COUNTIFS(Partite!T:T,1,Partite!G:G,Palinsesto!G21)+COUNTIFS(Partite!W:W,1,Partite!I:I,Palinsesto!G21) -> 14 | AE21: =COUNTIFS(Partite!U:U,1,Partite!H:H,G21)+COUNTIFS(Partite!X:X,1,Partite!J:J,G21) -> 0 | AF21: =COUNTIFS(Partite!V:V,1,Partite!I:I,G21)+COUNTIFS(Partite!Y:Y,1,Partite!K:K,G21) -> 1
G22: =VLOOKUP($B$2+B21,Partite!$A$1:$Z$2322,9,FALSE) -> Pohang Steelers | H22: =IFERROR(VLOOKUP(G22,Classifica!$C$2:$R$131,3,FALSE),"") -> 8 | I22: =IFERROR(VLOOKUP(G22,Classifica!$C$2:$R$131,4,FALSE),"") -> 4 | J22: =IFERROR(VLOOKUP(G22,Classifica!$C$2:$R$131,5,FALSE),"") -> 6 | K22: =IFERROR(VLOOKUP(G22,Classifica!$C$2:$R$131,6,FALSE),"") -> 19 | L22: =IFERROR(VLOOKUP(G22,Classifica!$C$2:$R$131,7,FALSE),"") -> 16 | M22: =IFERROR(VLOOKUP(G22,Classifica!$C$2:$R$131,8,FALSE),"") -> 3 | N22: =IFERROR(VLOOKUP(G22,Classifica!$C$2:$R$131,9,FALSE),"") -> 28 | O22: =IFERROR(VLOOKUP(G22,Classifica!$C$2:$R$131,16,FALSE),"") -> 5 | P22: =IFERROR(MID(INDEX(Classifica!M:M, MATCH(G22, Classifica!C:C, 0)), 1, 1), "") -> W | Q22: =IFERROR(MID(INDEX(Classifica!M:M, MATCH(G22, Classifica!C:C, 0)), 3, 1), "") -> L | R22: =IFERROR(MID(INDEX(Classifica!M:M, MATCH(G22, Classifica!C:C, 0)), 5, 1), "") -> W | S22: =IFERROR(MID(INDEX(Classifica!M:M, MATCH(G22, Classifica!C:C, 0)), 7, 1), "") -> W | T22: =IFERROR(MID(INDEX(Classifica!M:M, MATCH(G22, Classifica!C:C, 0)), 9, 1), "") -> L | U22: =IFERROR(IF(P22="","",COUNTIF(P22:T22,"W")*20+COUNTIF(P22:T22,"D")*7),"") -> 60 | W22: =COUNTIFS(Partite!AE:AE,1,Partite!Q:Q,Palinsesto!G22)+COUNTIFS(Partite!AE:AE,1,Partite!S:S,Palinsesto!G22) -> 0 | Y22: =INDEX(AD$4:AF$4, MATCH(MAX(AD22:AF22), AD22:AF22, 0)) -> 0-2 | Z22: =IFERROR(INT((LARGE(AD22:AF22,1)/SUM(H22:J22))*100),"") -> 88 | AA22: =COUNTIFS(Partite!AL:AL,1,Partite!Q:Q,Palinsesto!G22)+COUNTIFS(Partite!AL:AL,1,Partite!S:S,Palinsesto!G22) -> 0 | AD22: =COUNTIFS(Partite!T:T,1,Partite!G:G,Palinsesto!G22)+COUNTIFS(Partite!W:W,1,Partite!I:I,Palinsesto!G22) -> 16 | AE22: =COUNTIFS(Partite!U:U,1,Partite!H:H,G22)+COUNTIFS(Partite!X:X,1,Partite!J:J,G22) -> 0 | AF22: =COUNTIFS(Partite!V:V,1,Partite!I:I,G22)+COUNTIFS(Partite!Y:Y,1,Partite!K:K,G22) -> 4
B24: =B21+1 -> 7 | C24: =VLOOKUP($B$2+B24,Partite!$A$1:$Z$2322,2,FALSE) -> K League 1 | D24: =VLOOKUP($B$2+B24,Partite!$A$1:$Z$2322,3,FALSE) -> 19 | E24: =VALUE(TEXT(AC24, "GG/MM/AAAA")) -> 46225 | F24: =VLOOKUP($B$2+B24,Partite!$A$1:$Z$2322,6,FALSE) -> 19:30 (12:30) | G24: =VLOOKUP($B$2+B24,Partite!$A$1:$Z$2322,7,FALSE) -> Gwangju FC | H24: =IFERROR(VLOOKUP(G24,Classifica!$C$2:$R$131,3,FALSE),"") -> 1 | I24: =IFERROR(VLOOKUP(G24,Classifica!$C$2:$R$131,4,FALSE),"") -> 5 | J24: =IFERROR(VLOOKUP(G24,Classifica!$C$2:$R$131,5,FALSE),"") -> 11 | K24: =IFERROR(VLOOKUP(G24,Classifica!$C$2:$R$131,6,FALSE),"") -> 8 | L24: =IFERROR(VLOOKUP(G24,Classifica!$C$2:$R$131,7,FALSE),"") -> 41 | M24: =IFERROR(VLOOKUP(G24,Classifica!$C$2:$R$131,8,FALSE),"") -> -33 | N24: =IFERROR(VLOOKUP(G24,Classifica!$C$2:$R$131,9,FALSE),"") -> 8 | O24: =IFERROR(VLOOKUP(G24,Classifica!$C$2:$R$131,16,FALSE),"") -> 12 | P24: =IFERROR(MID(INDEX(Classifica!M:M, MATCH(G24, Classifica!C:C, 0)), 1, 1), "") -> D | Q24: =IFERROR(MID(INDEX(Classifica!M:M, MATCH(G24, Classifica!C:C, 0)), 3, 1), "") -> L | R24: =IFERROR(MID(INDEX(Classifica!M:M, MATCH(G24, Classifica!C:C, 0)), 5, 1), "") -> L | S24: =IFERROR(MID(INDEX(Classifica!M:M, MATCH(G24, Classifica!C:C, 0)), 7, 1), "") -> D | T24: =IFERROR(MID(INDEX(Classifica!M:M, MATCH(G24, Classifica!C:C, 0)), 9, 1), "") -> L | U24: =IFERROR(IF(P24="","",COUNTIF(P24:T24,"W")*20+COUNTIF(P24:T24,"D")*7),"") -> 14 | V24: =IFERROR(ABS(U24-U25),"") -> 7 | W24: =COUNTIFS(Partite!AE:AE,1,Partite!Q:Q,Palinsesto!G24)+COUNTIFS(Partite!AE:AE,1,Partite!S:S,Palinsesto!G24) -> 0 | X24: =IFERROR(AVERAGE(IFERROR(INT(W24/(SUM(H24:J24))*100),""),IFERROR(INT(W25/(SUM(H25:J25))*100),"")),"") -> 0 | Y24: =INDEX(AD$4:AF$4, MATCH(MAX(AD24:AF24), AD24:AF24, 0)) -> 0-2 | Z24: =IFERROR(INT((LARGE(AD24:AF24,1)/SUM(H24:J24))*100),"") -> 94 | AA24: =COUNTIFS(Partite!AL:AL,1,Partite!Q:Q,Palinsesto!G24)+COUNTIFS(Partite!AL:AL,1,Partite!S:S,Palinsesto!G24) -> 0 | AB24: =IFERROR(INT(AVERAGE(AA24/(SUM(H24:J24))*100,(AA25/(SUM(H25:J25))*100))),"") -> 0 | AC24: =VLOOKUP($B$2+B24,Partite!$A$1:$E$2322,5,FALSE) -> 2026-07-22 | AD24: =COUNTIFS(Partite!T:T,1,Partite!G:G,Palinsesto!G24)+COUNTIFS(Partite!W:W,1,Partite!I:I,Palinsesto!G24) -> 16 | AE24: =COUNTIFS(Partite!U:U,1,Partite!H:H,G24)+COUNTIFS(Partite!X:X,1,Partite!J:J,G24) -> 0 | AF24: =COUNTIFS(Partite!V:V,1,Partite!I:I,G24)+COUNTIFS(Partite!Y:Y,1,Partite!K:K,G24) -> 5
G25: =VLOOKUP($B$2+B24,Partite!$A$1:$Z$2322,9,FALSE) -> Sangmu | H25: =IFERROR(VLOOKUP(G25,Classifica!$C$2:$R$131,3,FALSE),"") -> 2 | I25: =IFERROR(VLOOKUP(G25,Classifica!$C$2:$R$131,4,FALSE),"") -> 10 | J25: =IFERROR(VLOOKUP(G25,Classifica!$C$2:$R$131,5,FALSE),"") -> 6 | K25: =IFERROR(VLOOKUP(G25,Classifica!$C$2:$R$131,6,FALSE),"") -> 17 | L25: =IFERROR(VLOOKUP(G25,Classifica!$C$2:$R$131,7,FALSE),"") -> 25 | M25: =IFERROR(VLOOKUP(G25,Classifica!$C$2:$R$131,8,FALSE),"") -> -8 | N25: =IFERROR(VLOOKUP(G25,Classifica!$C$2:$R$131,9,FALSE),"") -> 16 | O25: =IFERROR(VLOOKUP(G25,Classifica!$C$2:$R$131,16,FALSE),"") -> 11 | P25: =IFERROR(MID(INDEX(Classifica!M:M, MATCH(G25, Classifica!C:C, 0)), 1, 1), "") -> D | Q25: =IFERROR(MID(INDEX(Classifica!M:M, MATCH(G25, Classifica!C:C, 0)), 3, 1), "") -> L | R25: =IFERROR(MID(INDEX(Classifica!M:M, MATCH(G25, Classifica!C:C, 0)), 5, 1), "") -> D | S25: =IFERROR(MID(INDEX(Classifica!M:M, MATCH(G25, Classifica!C:C, 0)), 7, 1), "") -> D | T25: =IFERROR(MID(INDEX(Classifica!M:M, MATCH(G25, Classifica!C:C, 0)), 9, 1), "") -> L | U25: =IFERROR(IF(P25="","",COUNTIF(P25:T25,"W")*20+COUNTIF(P25:T25,"D")*7),"") -> 21 | W25: =COUNTIFS(Partite!AE:AE,1,Partite!Q:Q,Palinsesto!G25)+COUNTIFS(Partite!AE:AE,1,Partite!S:S,Palinsesto!G25) -> 0 | Y25: =INDEX(AD$4:AF$4, MATCH(MAX(AD25:AF25), AD25:AF25, 0)) -> 0-2 | Z25: =IFERROR(INT((LARGE(AD25:AF25,1)/SUM(H25:J25))*100),"") -> 94 | AA25: =COUNTIFS(Partite!AL:AL,1,Partite!Q:Q,Palinsesto!G25)+COUNTIFS(Partite!AL:AL,1,Partite!S:S,Palinsesto!G25) -> 0 | AD25: =COUNTIFS(Partite!T:T,1,Partite!G:G,Palinsesto!G25)+COUNTIFS(Partite!W:W,1,Partite!I:I,Palinsesto!G25) -> 17 | AE25: =COUNTIFS(Partite!U:U,1,Partite!H:H,G25)+COUNTIFS(Partite!X:X,1,Partite!J:J,G25) -> 0 | AF25: =COUNTIFS(Partite!V:V,1,Partite!I:I,G25)+COUNTIFS(Partite!Y:Y,1,Partite!K:K,G25) -> 4
B27: =B24+1 -> 8 | C27: =VLOOKUP($B$2+B27,Partite!$A$1:$Z$2322,2,FALSE) -> K League 1 | D27: =VLOOKUP($B$2+B27,Partite!$A$1:$Z$2322,3,FALSE) -> 19 | E27: =VALUE(TEXT(AC27, "GG/MM/AAAA")) -> 46225 | F27: =VLOOKUP($B$2+B27,Partite!$A$1:$Z$2322,6,FALSE) -> 19:30 (12:30) | G27: =VLOOKUP($B$2+B27,Partite!$A$1:$Z$2322,7,FALSE) -> Bucheon FC | H27: =IFERROR(VLOOKUP(G27,Classifica!$C$2:$R$131,3,FALSE),"") -> 4 | I27: =IFERROR(VLOOKUP(G27,Classifica!$C$2:$R$131,4,FALSE),"") -> 7 | J27: =IFERROR(VLOOKUP(G27,Classifica!$C$2:$R$131,5,FALSE),"") -> 6 | K27: =IFERROR(VLOOKUP(G27,Classifica!$C$2:$R$131,6,FALSE),"") -> 14 | L27: =IFERROR(VLOOKUP(G27,Classifica!$C$2:$R$131,7,FALSE),"") -> 18 | M27: =IFERROR(VLOOKUP(G27,Classifica!$C$2:$R$131,8,FALSE),"") -> -4 | N27: =IFERROR(VLOOKUP(G27,Classifica!$C$2:$R$131,9,FALSE),"") -> 19 | O27: =IFERROR(VLOOKUP(G27,Classifica!$C$2:$R$131,16,FALSE),"") -> 10 | P27: =IFERROR(MID(INDEX(Classifica!M:M, MATCH(G27, Classifica!C:C, 0)), 1, 1), "") -> L | Q27: =IFERROR(MID(INDEX(Classifica!M:M, MATCH(G27, Classifica!C:C, 0)), 3, 1), "") -> D | R27: =IFERROR(MID(INDEX(Classifica!M:M, MATCH(G27, Classifica!C:C, 0)), 5, 1), "") -> W | S27: =IFERROR(MID(INDEX(Classifica!M:M, MATCH(G27, Classifica!C:C, 0)), 7, 1), "") -> D | T27: =IFERROR(MID(INDEX(Classifica!M:M, MATCH(G27, Classifica!C:C, 0)), 9, 1), "") -> D | U27: =IFERROR(IF(P27="","",COUNTIF(P27:T27,"W")*20+COUNTIF(P27:T27,"D")*7),"") -> 41 | V27: =IFERROR(ABS(U27-U28),"") -> 13 | W27: =COUNTIFS(Partite!AE:AE,1,Partite!Q:Q,Palinsesto!G27)+COUNTIFS(Partite!AE:AE,1,Partite!S:S,Palinsesto!G27) -> 0 | X27: =IFERROR(AVERAGE(IFERROR(INT(W27/(SUM(H27:J27))*100),""),IFERROR(INT(W28/(SUM(H28:J28))*100),"")),"") -> 0 | Y27: =INDEX(AD$4:AF$4, MATCH(MAX(AD27:AF27), AD27:AF27, 0)) -> 0-2 | Z27: =IFERROR(INT((LARGE(AD27:AF27,1)/SUM(H27:J27))*100),"") -> 94 | AA27: =COUNTIFS(Partite!AL:AL,1,Partite!Q:Q,Palinsesto!G27)+COUNTIFS(Partite!AL:AL,1,Partite!S:S,Palinsesto!G27) -> 0 | AB27: =IFERROR(INT(AVERAGE(AA27/(SUM(H27:J27))*100,(AA28/(SUM(H28:J28))*100))),"") -> 0 | AC27: =VLOOKUP($B$2+B27,Partite!$A$1:$E$2322,5,FALSE) -> 2026-07-22 | AD27: =COUNTIFS(Partite!T:T,1,Partite!G:G,Palinsesto!G27)+COUNTIFS(Partite!W:W,1,Partite!I:I,Palinsesto!G27) -> 16 | AE27: =COUNTIFS(Partite!U:U,1,Partite!H:H,G27)+COUNTIFS(Partite!X:X,1,Partite!J:J,G27) -> 0 | AF27: =COUNTIFS(Partite!V:V,1,Partite!I:I,G27)+COUNTIFS(Partite!Y:Y,1,Partite!K:K,G27) -> 3
G28: =VLOOKUP($B$2+B27,Partite!$A$1:$Z$2322,9,FALSE) -> FC Anyang | H28: =IFERROR(VLOOKUP(G28,Classifica!$C$2:$R$131,3,FALSE),"") -> 5 | I28: =IFERROR(VLOOKUP(G28,Classifica!$C$2:$R$131,4,FALSE),"") -> 8 | J28: =IFERROR(VLOOKUP(G28,Classifica!$C$2:$R$131,5,FALSE),"") -> 4 | K28: =IFERROR(VLOOKUP(G28,Classifica!$C$2:$R$131,6,FALSE),"") -> 22 | L28: =IFERROR(VLOOKUP(G28,Classifica!$C$2:$R$131,7,FALSE),"") -> 19 | M28: =IFERROR(VLOOKUP(G28,Classifica!$C$2:$R$131,8,FALSE),"") -> 3 | N28: =IFERROR(VLOOKUP(G28,Classifica!$C$2:$R$131,9,FALSE),"") -> 23 | O28: =IFERROR(VLOOKUP(G28,Classifica!$C$2:$R$131,16,FALSE),"") -> 7 | P28: =IFERROR(MID(INDEX(Classifica!M:M, MATCH(G28, Classifica!C:C, 0)), 1, 1), "") -> D | Q28: =IFERROR(MID(INDEX(Classifica!M:M, MATCH(G28, Classifica!C:C, 0)), 3, 1), "") -> D | R28: =IFERROR(MID(INDEX(Classifica!M:M, MATCH(G28, Classifica!C:C, 0)), 5, 1), "") -> W | S28: =IFERROR(MID(INDEX(Classifica!M:M, MATCH(G28, Classifica!C:C, 0)), 7, 1), "") -> L | T28: =IFERROR(MID(INDEX(Classifica!M:M, MATCH(G28, Classifica!C:C, 0)), 9, 1), "") -> W | U28: =IFERROR(IF(P28="","",COUNTIF(P28:T28,"W")*20+COUNTIF(P28:T28,"D")*7),"") -> 54 | W28: =COUNTIFS(Partite!AE:AE,1,Partite!Q:Q,Palinsesto!G28)+COUNTIFS(Partite!AE:AE,1,Partite!S:S,Palinsesto!G28) -> 0 | Y28: =INDEX(AD$4:AF$4, MATCH(MAX(AD28:AF28), AD28:AF28, 0)) -> 0-2 | Z28: =IFERROR(INT((LARGE(AD28:AF28,1)/SUM(H28:J28))*100),"") -> 94 | AA28: =COUNTIFS(Partite!AL:AL,1,Partite!Q:Q,Palinsesto!G28)+COUNTIFS(Partite!AL:AL,1,Partite!S:S,Palinsesto!G28) -> 0 | AD28: =COUNTIFS(Partite!T:T,1,Partite!G:G,Palinsesto!G28)+COUNTIFS(Partite!W:W,1,Partite!I:I,Palinsesto!G28) -> 16 | AE28: =COUNTIFS(Partite!U:U,1,Partite!H:H,G28)+COUNTIFS(Partite!X:X,1,Partite!J:J,G28) -> 0 | AF28: =COUNTIFS(Partite!V:V,1,Partite!I:I,G28)+COUNTIFS(Partite!Y:Y,1,Partite!K:K,G28) -> 2
B30: =B27+1 -> 9 | C30: =VLOOKUP($B$2+B30,Partite!$A$1:$Z$2322,2,FALSE) -> Europa League | D30: =VLOOKUP($B$2+B30,Partite!$A$1:$Z$2322,3,FALSE) -> 0 | E30: =VALUE(TEXT(AC30, "GG/MM/AAAA")) -> 46226 | F30: =VLOOKUP($B$2+B30,Partite!$A$1:$Z$2322,6,FALSE) -> 19:00 | G30: =VLOOKUP($B$2+B30,Partite!$A$1:$Z$2322,7,FALSE) -> Tromsø no | H30: =IFERROR(VLOOKUP(G30,Classifica!$C$2:$R$131,3,FALSE),"") | I30: =IFERROR(VLOOKUP(G30,Classifica!$C$2:$R$131,4,FALSE),"") | J30: =IFERROR(VLOOKUP(G30,Classifica!$C$2:$R$131,5,FALSE),"") | K30: =IFERROR(VLOOKUP(G30,Classifica!$C$2:$R$131,6,FALSE),"") | L30: =IFERROR(VLOOKUP(G30,Classifica!$C$2:$R$131,7,FALSE),"") | M30: =IFERROR(VLOOKUP(G30,Classifica!$C$2:$R$131,8,FALSE),"") | N30: =IFERROR(VLOOKUP(G30,Classifica!$C$2:$R$131,9,FALSE),"") | O30: =IFERROR(VLOOKUP(G30,Classifica!$C$2:$R$131,16,FALSE),"") | P30: =IFERROR(MID(INDEX(Classifica!M:M, MATCH(G30, Classifica!C:C, 0)), 1, 1), "") | Q30: =IFERROR(MID(INDEX(Classifica!M:M, MATCH(G30, Classifica!C:C, 0)), 3, 1), "") | R30: =IFERROR(MID(INDEX(Classifica!M:M, MATCH(G30, Classifica!C:C, 0)), 5, 1), "") | S30: =IFERROR(MID(INDEX(Classifica!M:M, MATCH(G30, Classifica!C:C, 0)), 7, 1), "") | T30: =IFERROR(MID(INDEX(Classifica!M:M, MATCH(G30, Classifica!C:C, 0)), 9, 1), "") | U30: =IFERROR(IF(P30="","",COUNTIF(P30:T30,"W")*20+COUNTIF(P30:T30,"D")*7),"") | V30: =IFERROR(ABS(U30-U31),"") | W30: =COUNTIFS(Partite!AE:AE,1,Partite!Q:Q,Palinsesto!G30)+COUNTIFS(Partite!AE:AE,1,Partite!S:S,Palinsesto!G30) -> 0 | X30: =IFERROR(AVERAGE(IFERROR(INT(W30/(SUM(H30:J30))*100),""),IFERROR(INT(W31/(SUM(H31:J31))*100),"")),"") | Y30: =INDEX(AD$4:AF$4, MATCH(MAX(AD30:AF30), AD30:AF30, 0)) -> 0-2 | Z30: =IFERROR(INT((LARGE(AD30:AF30,1)/SUM(H30:J30))*100),"") | AA30: =COUNTIFS(Partite!AL:AL,1,Partite!Q:Q,Palinsesto!G30)+COUNTIFS(Partite!AL:AL,1,Partite!S:S,Palinsesto!G30) -> 0 | AB30: =IFERROR(INT(AVERAGE(AA30/(SUM(H30:J30))*100,(AA31/(SUM(H31:J31))*100))),"") | AC30: =VLOOKUP($B$2+B30,Partite!$A$1:$E$2322,5,FALSE) -> 2026-07-23 | AD30: =COUNTIFS(Partite!T:T,1,Partite!G:G,Palinsesto!G30)+COUNTIFS(Partite!W:W,1,Partite!I:I,Palinsesto!G30) -> 0 | AE30: =COUNTIFS(Partite!U:U,1,Partite!H:H,G30)+COUNTIFS(Partite!X:X,1,Partite!J:J,G30) -> 0 | AF30: =COUNTIFS(Partite!V:V,1,Partite!I:I,G30)+COUNTIFS(Partite!Y:Y,1,Partite!K:K,G30) -> 0
G31: =VLOOKUP($B$2+B30,Partite!$A$1:$Z$2322,9,FALSE) -> cz Hradec Králové | H31: =IFERROR(VLOOKUP(G31,Classifica!$C$2:$R$131,3,FALSE),"") | I31: =IFERROR(VLOOKUP(G31,Classifica!$C$2:$R$131,4,FALSE),"") | J31: =IFERROR(VLOOKUP(G31,Classifica!$C$2:$R$131,5,FALSE),"") | K31: =IFERROR(VLOOKUP(G31,Classifica!$C$2:$R$131,6,FALSE),"") | L31: =IFERROR(VLOOKUP(G31,Classifica!$C$2:$R$131,7,FALSE),"") | M31: =IFERROR(VLOOKUP(G31,Classifica!$C$2:$R$131,8,FALSE),"") | N31: =IFERROR(VLOOKUP(G31,Classifica!$C$2:$R$131,9,FALSE),"") | O31: =IFERROR(VLOOKUP(G31,Classifica!$C$2:$R$131,16,FALSE),"") | P31: =IFERROR(MID(INDEX(Classifica!M:M, MATCH(G31, Classifica!C:C, 0)), 1, 1), "") | Q31: =IFERROR(MID(INDEX(Classifica!M:M, MATCH(G31, Classifica!C:C, 0)), 3, 1), "") | R31: =IFERROR(MID(INDEX(Classifica!M:M, MATCH(G31, Classifica!C:C, 0)), 5, 1), "") | S31: =IFERROR(MID(INDEX(Classifica!M:M, MATCH(G31, Classifica!C:C, 0)), 7, 1), "") | T31: =IFERROR(MID(INDEX(Classifica!M:M, MATCH(G31, Classifica!C:C, 0)), 9, 1), "") | U31: =IFERROR(IF(P31="","",COUNTIF(P31:T31,"W")*20+COUNTIF(P31:T31,"D")*7),"") | W31: =COUNTIFS(Partite!AE:AE,1,Partite!Q:Q,Palinsesto!G31)+COUNTIFS(Partite!AE:AE,1,Partite!S:S,Palinsesto!G31) -> 0 | Y31: =INDEX(AD$4:AF$4, MATCH(MAX(AD31:AF31), AD31:AF31, 0)) -> 0-2 | Z31: =IFERROR(INT((LARGE(AD31:AF31,1)/SUM(H31:J31))*100),"") | AA31: =COUNTIFS(Partite!AL:AL,1,Partite!Q:Q,Palinsesto!G31)+COUNTIFS(Partite!AL:AL,1,Partite!S:S,Palinsesto!G31) -> 0 | AD31: =COUNTIFS(Partite!T:T,1,Partite!G:G,Palinsesto!G31)+COUNTIFS(Partite!W:W,1,Partite!I:I,Palinsesto!G31) -> 0 | AE31: =COUNTIFS(Partite!U:U,1,Partite!H:H,G31)+COUNTIFS(Partite!X:X,1,Partite!J:J,G31) -> 0 | AF31: =COUNTIFS(Partite!V:V,1,Partite!I:I,G31)+COUNTIFS(Partite!Y:Y,1,Partite!K:K,G31) -> 0
B33: =B30+1 -> 10 | C33: =VLOOKUP($B$2+B33,Partite!$A$1:$Z$2322,2,FALSE) -> Europa League | D33: =VLOOKUP($B$2+B33,Partite!$A$1:$Z$2322,3,FALSE) -> 0 | E33: =VALUE(TEXT(AC33, "GG/MM/AAAA")) -> 46226 | F33: =VLOOKUP($B$2+B33,Partite!$A$1:$Z$2322,6,FALSE) -> 19:00 | G33: =VLOOKUP($B$2+B33,Partite!$A$1:$Z$2322,7,FALSE) -> Dynamo Kyiv ua | H33: =IFERROR(VLOOKUP(G33,Classifica!$C$2:$R$131,3,FALSE),"") | I33: =IFERROR(VLOOKUP(G33,Classifica!$C$2:$R$131,4,FALSE),"") | J33: =IFERROR(VLOOKUP(G33,Classifica!$C$2:$R$131,5,FALSE),"") | K33: =IFERROR(VLOOKUP(G33,Classifica!$C$2:$R$131,6,FALSE),"") | L33: =IFERROR(VLOOKUP(G33,Classifica!$C$2:$R$131,7,FALSE),"") | M33: =IFERROR(VLOOKUP(G33,Classifica!$C$2:$R$131,8,FALSE),"") | N33: =IFERROR(VLOOKUP(G33,Classifica!$C$2:$R$131,9,FALSE),"") | O33: =IFERROR(VLOOKUP(G33,Classifica!$C$2:$R$131,16,FALSE),"") | P33: =IFERROR(MID(INDEX(Classifica!M:M, MATCH(G33, Classifica!C:C, 0)), 1, 1), "") | Q33: =IFERROR(MID(INDEX(Classifica!M:M, MATCH(G33, Classifica!C:C, 0)), 3, 1), "") | R33: =IFERROR(MID(INDEX(Classifica!M:M, MATCH(G33, Classifica!C:C, 0)), 5, 1), "") | S33: =IFERROR(MID(INDEX(Classifica!M:M, MATCH(G33, Classifica!C:C, 0)), 7, 1), "") | T33: =IFERROR(MID(INDEX(Classifica!M:M, MATCH(G33, Classifica!C:C, 0)), 9, 1), "") | U33: =IFERROR(IF(P33="","",COUNTIF(P33:T33,"W")*20+COUNTIF(P33:T33,"D")*7),"") | V33: =IFERROR(ABS(U33-U34),"") | W33: =COUNTIFS(Partite!AE:AE,1,Partite!Q:Q,Palinsesto!G33)+COUNTIFS(Partite!AE:AE,1,Partite!S:S,Palinsesto!G33) -> 0 | X33: =IFERROR(AVERAGE(IFERROR(INT(W33/(SUM(H33:J33))*100),""),IFERROR(INT(W34/(SUM(H34:J34))*100),"")),"") | Y33: =INDEX(AD$4:AF$4, MATCH(MAX(AD33:AF33), AD33:AF33, 0)) -> 0-2 | Z33: =IFERROR(INT((LARGE(AD33:AF33,1)/SUM(H33:J33))*100),"") | AA33: =COUNTIFS(Partite!AL:AL,1,Partite!Q:Q,Palinsesto!G33)+COUNTIFS(Partite!AL:AL,1,Partite!S:S,Palinsesto!G33) -> 0 | AB33: =IFERROR(INT(AVERAGE(AA33/(SUM(H33:J33))*100,(AA34/(SUM(H34:J34))*100))),"") | AC33: =VLOOKUP($B$2+B33,Partite!$A$1:$E$2322,5,FALSE) -> 2026-07-23 | AD33: =COUNTIFS(Partite!T:T,1,Partite!G:G,Palinsesto!G33)+COUNTIFS(Partite!W:W,1,Partite!I:I,Palinsesto!G33) -> 1 | AE33: =COUNTIFS(Partite!U:U,1,Partite!H:H,G33)+COUNTIFS(Partite!X:X,1,Partite!J:J,G33) -> 0 | AF33: =COUNTIFS(Partite!V:V,1,Partite!I:I,G33)+COUNTIFS(Partite!Y:Y,1,Partite!K:K,G33) -> 0
G34: =VLOOKUP($B$2+B33,Partite!$A$1:$Z$2322,9,FALSE) -> gr PAOK | H34: =IFERROR(VLOOKUP(G34,Classifica!$C$2:$R$131,3,FALSE),"") | I34: =IFERROR(VLOOKUP(G34,Classifica!$C$2:$R$131,4,FALSE),"") | J34: =IFERROR(VLOOKUP(G34,Classifica!$C$2:$R$131,5,FALSE),"") | K34: =IFERROR(VLOOKUP(G34,Classifica!$C$2:$R$131,6,FALSE),"") | L34: =IFERROR(VLOOKUP(G34,Classifica!$C$2:$R$131,7,FALSE),"") | M34: =IFERROR(VLOOKUP(G34,Classifica!$C$2:$R$131,8,FALSE),"") | N34: =IFERROR(VLOOKUP(G34,Classifica!$C$2:$R$131,9,FALSE),"") | O34: =IFERROR(VLOOKUP(G34,Classifica!$C$2:$R$131,16,FALSE),"") | P34: =IFERROR(MID(INDEX(Classifica!M:M, MATCH(G34, Classifica!C:C, 0)), 1, 1), "") | Q34: =IFERROR(MID(INDEX(Classifica!M:M, MATCH(G34, Classifica!C:C, 0)), 3, 1), "") | R34: =IFERROR(MID(INDEX(Classifica!M:M, MATCH(G34, Classifica!C:C, 0)), 5, 1), "") | S34: =IFERROR(MID(INDEX(Classifica!M:M, MATCH(G34, Classifica!C:C, 0)), 7, 1), "") | T34: =IFERROR(MID(INDEX(Classifica!M:M, MATCH(G34, Classifica!C:C, 0)), 9, 1), "") | U34: =IFERROR(IF(P34="","",COUNTIF(P34:T34,"W")*20+COUNTIF(P34:T34,"D")*7),"") | W34: =COUNTIFS(Partite!AE:AE,1,Partite!Q:Q,Palinsesto!G34)+COUNTIFS(Partite!AE:AE,1,Partite!S:S,Palinsesto!G34) -> 0 | Y34: =INDEX(AD$4:AF$4, MATCH(MAX(AD34:AF34), AD34:AF34, 0)) -> 0-2 | Z34: =IFERROR(INT((LARGE(AD34:AF34,1)/SUM(H34:J34))*100),"") | AA34: =COUNTIFS(Partite!AL:AL,1,Partite!Q:Q,Palinsesto!G34)+COUNTIFS(Partite!AL:AL,1,Partite!S:S,Palinsesto!G34) -> 0 | AD34: =COUNTIFS(Partite!T:T,1,Partite!G:G,Palinsesto!G34)+COUNTIFS(Partite!W:W,1,Partite!I:I,Palinsesto!G34) -> 0 | AE34: =COUNTIFS(Partite!U:U,1,Partite!H:H,G34)+COUNTIFS(Partite!X:X,1,Partite!J:J,G34) -> 0 | AF34: =COUNTIFS(Partite!V:V,1,Partite!I:I,G34)+COUNTIFS(Partite!Y:Y,1,Partite!K:K,G34) -> 0
B36: =B33+1 -> 11 | C36: =VLOOKUP($B$2+B36,Partite!$A$1:$Z$2322,2,FALSE) -> Europa League | D36: =VLOOKUP($B$2+B36,Partite!$A$1:$Z$2322,3,FALSE) -> 0 | E36: =VALUE(TEXT(AC36, "GG/MM/AAAA")) -> 46226 | F36: =VLOOKUP($B$2+B36,Partite!$A$1:$Z$2322,6,FALSE) -> 19:00 | G36: =VLOOKUP($B$2+B36,Partite!$A$1:$Z$2322,7,FALSE) -> Hammarby se | H36: =IFERROR(VLOOKUP(G36,Classifica!$C$2:$R$131,3,FALSE),"") | I36: =IFERROR(VLOOKUP(G36,Classifica!$C$2:$R$131,4,FALSE),"") | J36: =IFERROR(VLOOKUP(G36,Classifica!$C$2:$R$131,5,FALSE),"") | K36: =IFERROR(VLOOKUP(G36,Classifica!$C$2:$R$131,6,FALSE),"") | L36: =IFERROR(VLOOKUP(G36,Classifica!$C$2:$R$131,7,FALSE),"") | M36: =IFERROR(VLOOKUP(G36,Classifica!$C$2:$R$131,8,FALSE),"") | N36: =IFERROR(VLOOKUP(G36,Classifica!$C$2:$R$131,9,FALSE),"") | O36: =IFERROR(VLOOKUP(G36,Classifica!$C$2:$R$131,16,FALSE),"") | P36: =IFERROR(MID(INDEX(Classifica!M:M, MATCH(G36, Classifica!C:C, 0)), 1, 1), "") | Q36: =IFERROR(MID(INDEX(Classifica!M:M, MATCH(G36, Classifica!C:C, 0)), 3, 1), "") | R36: =IFERROR(MID(INDEX(Classifica!M:M, MATCH(G36, Classifica!C:C, 0)), 5, 1), "") | S36: =IFERROR(MID(INDEX(Classifica!M:M, MATCH(G36, Classifica!C:C, 0)), 7, 1), "") | T36: =IFERROR(MID(INDEX(Classifica!M:M, MATCH(G36, Classifica!C:C, 0)), 9, 1), "") | U36: =IFERROR(IF(P36="","",COUNTIF(P36:T36,"W")*20+COUNTIF(P36:T36,"D")*7),"") | V36: =IFERROR(ABS(U36-U37),"") | W36: =COUNTIFS(Partite!AE:AE,1,Partite!Q:Q,Palinsesto!G36)+COUNTIFS(Partite!AE:AE,1,Partite!S:S,Palinsesto!G36) -> 0 | X36: =IFERROR(AVERAGE(IFERROR(INT(W36/(SUM(H36:J36))*100),""),IFERROR(INT(W37/(SUM(H37:J37))*100),"")),"") | Y36: =INDEX(AD$4:AF$4, MATCH(MAX(AD36:AF36), AD36:AF36, 0)) -> 0-2 | Z36: =IFERROR(INT((LARGE(AD36:AF36,1)/SUM(H36:J36))*100),"") | AA36: =COUNTIFS(Partite!AL:AL,1,Partite!Q:Q,Palinsesto!G36)+COUNTIFS(Partite!AL:AL,1,Partite!S:S,Palinsesto!G36) -> 0 | AB36: =IFERROR(INT(AVERAGE(AA36/(SUM(H36:J36))*100,(AA37/(SUM(H37:J37))*100))),"") | AC36: =VLOOKUP($B$2+B36,Partite!$A$1:$E$2322,5,FALSE) -> 2026-07-23 | AD36: =COUNTIFS(Partite!T:T,1,Partite!G:G,Palinsesto!G36)+COUNTIFS(Partite!W:W,1,Partite!I:I,Palinsesto!G36) -> 0 | AE36: =COUNTIFS(Partite!U:U,1,Partite!H:H,G36)+COUNTIFS(Partite!X:X,1,Partite!J:J,G36) -> 0 | AF36: =COUNTIFS(Partite!V:V,1,Partite!I:I,G36)+COUNTIFS(Partite!Y:Y,1,Partite!K:K,G36) -> 0
G37: =VLOOKUP($B$2+B36,Partite!$A$1:$Z$2322,9,FALSE) -> be Anderlecht | H37: =IFERROR(VLOOKUP(G37,Classifica!$C$2:$R$131,3,FALSE),"") | I37: =IFERROR(VLOOKUP(G37,Classifica!$C$2:$R$131,4,FALSE),"") | J37: =IFERROR(VLOOKUP(G37,Classifica!$C$2:$R$131,5,FALSE),"") | K37: =IFERROR(VLOOKUP(G37,Classifica!$C$2:$R$131,6,FALSE),"") | L37: =IFERROR(VLOOKUP(G37,Classifica!$C$2:$R$131,7,FALSE),"") | M37: =IFERROR(VLOOKUP(G37,Classifica!$C$2:$R$131,8,FALSE),"") | N37: =IFERROR(VLOOKUP(G37,Classifica!$C$2:$R$131,9,FALSE),"") | O37: =IFERROR(VLOOKUP(G37,Classifica!$C$2:$R$131,16,FALSE),"") | P37: =IFERROR(MID(INDEX(Classifica!M:M, MATCH(G37, Classifica!C:C, 0)), 1, 1), "") | Q37: =IFERROR(MID(INDEX(Classifica!M:M, MATCH(G37, Classifica!C:C, 0)), 3, 1), "") | R37: =IFERROR(MID(INDEX(Classifica!M:M, MATCH(G37, Classifica!C:C, 0)), 5, 1), "") | S37: =IFERROR(MID(INDEX(Classifica!M:M, MATCH(G37, Classifica!C:C, 0)), 7, 1), "") | T37: =IFERROR(MID(INDEX(Classifica!M:M, MATCH(G37, Classifica!C:C, 0)), 9, 1), "") | U37: =IFERROR(IF(P37="","",COUNTIF(P37:T37,"W")*20+COUNTIF(P37:T37,"D")*7),"") | W37: =COUNTIFS(Partite!AE:AE,1,Partite!Q:Q,Palinsesto!G37)+COUNTIFS(Partite!AE:AE,1,Partite!S:S,Palinsesto!G37) -> 0 | Y37: =INDEX(AD$4:AF$4, MATCH(MAX(AD37:AF37), AD37:AF37, 0)) -> 0-2 | Z37: =IFERROR(INT((LARGE(AD37:AF37,1)/SUM(H37:J37))*100),"") | AA37: =COUNTIFS(Partite!AL:AL,1,Partite!Q:Q,Palinsesto!G37)+COUNTIFS(Partite!AL:AL,1,Partite!S:S,Palinsesto!G37) -> 0 | AD37: =COUNTIFS(Partite!T:T,1,Partite!G:G,Palinsesto!G37)+COUNTIFS(Partite!W:W,1,Partite!I:I,Palinsesto!G37) -> 0 | AE37: =COUNTIFS(Partite!U:U,1,Partite!H:H,G37)+COUNTIFS(Partite!X:X,1,Partite!J:J,G37) -> 0 | AF37: =COUNTIFS(Partite!V:V,1,Partite!I:I,G37)+COUNTIFS(Partite!Y:Y,1,Partite!K:K,G37) -> 0
B39: =B36+1 -> 12 | C39: =VLOOKUP($B$2+B39,Partite!$A$1:$Z$2322,2,FALSE) -> Europa League | D39: =VLOOKUP($B$2+B39,Partite!$A$1:$Z$2322,3,FALSE) -> 0 | E39: =VALUE(TEXT(AC39, "GG/MM/AAAA")) -> 46226 | F39: =VLOOKUP($B$2+B39,Partite!$A$1:$Z$2322,6,FALSE) -> 20:00 (18:00) | G39: =VLOOKUP($B$2+B39,Partite!$A$1:$Z$2322,7,FALSE) -> Qarabağ az | H39: =IFERROR(VLOOKUP(G39,Classifica!$C$2:$R$131,3,FALSE),"") | I39: =IFERROR(VLOOKUP(G39,Classifica!$C$2:$R$131,4,FALSE),"") | J39: =IFERROR(VLOOKUP(G39,Classifica!$C$2:$R$131,5,FALSE),"") | K39: =IFERROR(VLOOKUP(G39,Classifica!$C$2:$R$131,6,FALSE),"") | L39: =IFERROR(VLOOKUP(G39,Classifica!$C$2:$R$131,7,FALSE),"") | M39: =IFERROR(VLOOKUP(G39,Classifica!$C$2:$R$131,8,FALSE),"") | N39: =IFERROR(VLOOKUP(G39,Classifica!$C$2:$R$131,9,FALSE),"") | O39: =IFERROR(VLOOKUP(G39,Classifica!$C$2:$R$131,16,FALSE),"") | P39: =IFERROR(MID(INDEX(Classifica!M:M, MATCH(G39, Classifica!C:C, 0)), 1, 1), "") | Q39: =IFERROR(MID(INDEX(Classifica!M:M, MATCH(G39, Classifica!C:C, 0)), 3, 1), "") | R39: =IFERROR(MID(INDEX(Classifica!M:M, MATCH(G39, Classifica!C:C, 0)), 5, 1), "") | S39: =IFERROR(MID(INDEX(Classifica!M:M, MATCH(G39, Classifica!C:C, 0)), 7, 1), "") | T39: =IFERROR(MID(INDEX(Classifica!M:M, MATCH(G39, Classifica!C:C, 0)), 9, 1), "") | U39: =IFERROR(IF(P39="","",COUNTIF(P39:T39,"W")*20+COUNTIF(P39:T39,"D")*7),"") | V39: =IFERROR(ABS(U39-U40),"") | W39: =COUNTIFS(Partite!AE:AE,1,Partite!Q:Q,Palinsesto!G39)+COUNTIFS(Partite!AE:AE,1,Partite!S:S,Palinsesto!G39) -> 0 | X39: =IFERROR(AVERAGE(IFERROR(INT(W39/(SUM(H39:J39))*100),""),IFERROR(INT(W40/(SUM(H40:J40))*100),"")),"") | Y39: =INDEX(AD$4:AF$4, MATCH(MAX(AD39:AF39), AD39:AF39, 0)) -> 0-2 | Z39: =IFERROR(INT((LARGE(AD39:AF39,1)/SUM(H39:J39))*100),"") | AA39: =COUNTIFS(Partite!AL:AL,1,Partite!Q:Q,Palinsesto!G39)+COUNTIFS(Partite!AL:AL,1,Partite!S:S,Palinsesto!G39) -> 0 | AB39: =IFERROR(INT(AVERAGE(AA39/(SUM(H39:J39))*100,(AA40/(SUM(H40:J40))*100))),"") | AC39: =VLOOKUP($B$2+B39,Partite!$A$1:$E$2322,5,FALSE) -> 2026-07-23 | AD39: =COUNTIFS(Partite!T:T,1,Partite!G:G,Palinsesto!G39)+COUNTIFS(Partite!W:W,1,Partite!I:I,Palinsesto!G39) -> 0 | AE39: =COUNTIFS(Partite!U:U,1,Partite!H:H,G39)+COUNTIFS(Partite!X:X,1,Partite!J:J,G39) -> 0 | AF39: =COUNTIFS(Partite!V:V,1,Partite!I:I,G39)+COUNTIFS(Partite!Y:Y,1,Partite!K:K,G39) -> 0
G40: =VLOOKUP($B$2+B39,Partite!$A$1:$Z$2322,9,FALSE) -> bg CSKA Sofia | H40: =IFERROR(VLOOKUP(G40,Classifica!$C$2:$R$131,3,FALSE),"") | I40: =IFERROR(VLOOKUP(G40,Classifica!$C$2:$R$131,4,FALSE),"") | J40: =IFERROR(VLOOKUP(G40,Classifica!$C$2:$R$131,5,FALSE),"") | K40: =IFERROR(VLOOKUP(G40,Classifica!$C$2:$R$131,6,FALSE),"") | L40: =IFERROR(VLOOKUP(G40,Classifica!$C$2:$R$131,7,FALSE),"") | M40: =IFERROR(VLOOKUP(G40,Classifica!$C$2:$R$131,8,FALSE),"") | N40: =IFERROR(VLOOKUP(G40,Classifica!$C$2:$R$131,9,FALSE),"") | O40: =IFERROR(VLOOKUP(G40,Classifica!$C$2:$R$131,16,FALSE),"") | P40: =IFERROR(MID(INDEX(Classifica!M:M, MATCH(G40, Classifica!C:C, 0)), 1, 1), "") | Q40: =IFERROR(MID(INDEX(Classifica!M:M, MATCH(G40, Classifica!C:C, 0)), 3, 1), "") | R40: =IFERROR(MID(INDEX(Classifica!M:M, MATCH(G40, Classifica!C:C, 0)), 5, 1), "") | S40: =IFERROR(MID(INDEX(Classifica!M:M, MATCH(G40, Classifica!C:C, 0)), 7, 1), "") | T40: =IFERROR(MID(INDEX(Classifica!M:M, MATCH(G40, Classifica!C:C, 0)), 9, 1), "") | U40: =IFERROR(IF(P40="","",COUNTIF(P40:T40,"W")*20+COUNTIF(P40:T40,"D")*7),"") | W40: =COUNTIFS(Partite!AE:AE,1,Partite!Q:Q,Palinsesto!G40)+COUNTIFS(Partite!AE:AE,1,Partite!S:S,Palinsesto!G40) -> 0 | Y40: =INDEX(AD$4:AF$4, MATCH(MAX(AD40:AF40), AD40:AF40, 0)) -> 0-2 | Z40: =IFERROR(INT((LARGE(AD40:AF40,1)/SUM(H40:J40))*100),"") | AA40: =COUNTIFS(Partite!AL:AL,1,Partite!Q:Q,Palinsesto!G40)+COUNTIFS(Partite!AL:AL,1,Partite!S:S,Palinsesto!G40) -> 0 | AD40: =COUNTIFS(Partite!T:T,1,Partite!G:G,Palinsesto!G40)+COUNTIFS(Partite!W:W,1,Partite!I:I,Palinsesto!G40) -> 1 | AE40: =COUNTIFS(Partite!U:U,1,Partite!H:H,G40)+COUNTIFS(Partite!X:X,1,Partite!J:J,G40) -> 0 | AF40: =COUNTIFS(Partite!V:V,1,Partite!I:I,G40)+COUNTIFS(Partite!Y:Y,1,Partite!K:K,G40) -> 0
B42: =B39+1 -> 13 | C42: =VLOOKUP($B$2+B42,Partite!$A$1:$Z$2322,2,FALSE) -> Europa League | D42: =VLOOKUP($B$2+B42,Partite!$A$1:$Z$2322,3,FALSE) -> 0 | E42: =VALUE(TEXT(AC42, "GG/MM/AAAA")) -> 46226 | F42: =VLOOKUP($B$2+B42,Partite!$A$1:$Z$2322,6,FALSE) -> 20:00 | G42: =VLOOKUP($B$2+B42,Partite!$A$1:$Z$2322,7,FALSE) -> St. Gallen ch | H42: =IFERROR(VLOOKUP(G42,Classifica!$C$2:$R$131,3,FALSE),"") | I42: =IFERROR(VLOOKUP(G42,Classifica!$C$2:$R$131,4,FALSE),"") | J42: =IFERROR(VLOOKUP(G42,Classifica!$C$2:$R$131,5,FALSE),"") | K42: =IFERROR(VLOOKUP(G42,Classifica!$C$2:$R$131,6,FALSE),"") | L42: =IFERROR(VLOOKUP(G42,Classifica!$C$2:$R$131,7,FALSE),"") | M42: =IFERROR(VLOOKUP(G42,Classifica!$C$2:$R$131,8,FALSE),"") | N42: =IFERROR(VLOOKUP(G42,Classifica!$C$2:$R$131,9,FALSE),"") | O42: =IFERROR(VLOOKUP(G42,Classifica!$C$2:$R$131,16,FALSE),"") | P42: =IFERROR(MID(INDEX(Classifica!M:M, MATCH(G42, Classifica!C:C, 0)), 1, 1), "") | Q42: =IFERROR(MID(INDEX(Classifica!M:M, MATCH(G42, Classifica!C:C, 0)), 3, 1), "") | R42: =IFERROR(MID(INDEX(Classifica!M:M, MATCH(G42, Classifica!C:C, 0)), 5, 1), "") | S42: =IFERROR(MID(INDEX(Classifica!M:M, MATCH(G42, Classifica!C:C, 0)), 7, 1), "") | T42: =IFERROR(MID(INDEX(Classifica!M:M, MATCH(G42, Classifica!C:C, 0)), 9, 1), "") | U42: =IFERROR(IF(P42="","",COUNTIF(P42:T42,"W")*20+COUNTIF(P42:T42,"D")*7),"") | V42: =IFERROR(ABS(U42-U43),"") | W42: =COUNTIFS(Partite!AE:AE,1,Partite!Q:Q,Palinsesto!G42)+COUNTIFS(Partite!AE:AE,1,Partite!S:S,Palinsesto!G42) -> 0 | X42: =IFERROR(AVERAGE(IFERROR(INT(W42/(SUM(H42:J42))*100),""),IFERROR(INT(W43/(SUM(H43:J43))*100),"")),"") | Y42: =INDEX(AD$4:AF$4, MATCH(MAX(AD42:AF42), AD42:AF42, 0)) -> 0-2 | Z42: =IFERROR(INT((LARGE(AD42:AF42,1)/SUM(H42:J42))*100),"") | AA42: =COUNTIFS(Partite!AL:AL,1,Partite!Q:Q,Palinsesto!G42)+COUNTIFS(Partite!AL:AL,1,Partite!S:S,Palinsesto!G42) -> 0 | AB42: =IFERROR(INT(AVERAGE(AA42/(SUM(H42:J42))*100,(AA43/(SUM(H43:J43))*100))),"") | AC42: =VLOOKUP($B$2+B42,Partite!$A$1:$E$2322,5,FALSE) -> 2026-07-23 | AD42: =COUNTIFS(Partite!T:T,1,Partite!G:G,Palinsesto!G42)+COUNTIFS(Partite!W:W,1,Partite!I:I,Palinsesto!G42) -> 0 | AE42: =COUNTIFS(Partite!U:U,1,Partite!H:H,G42)+COUNTIFS(Partite!X:X,1,Partite!J:J,G42) -> 0 | AF42: =COUNTIFS(Partite!V:V,1,Partite!I:I,G42)+COUNTIFS(Partite!Y:Y,1,Partite!K:K,G42) -> 0
G43: =VLOOKUP($B$2+B42,Partite!$A$1:$Z$2322,9,FALSE) -> pt Benfica | H43: =IFERROR(VLOOKUP(G43,Classifica!$C$2:$R$131,3,FALSE),"") | I43: =IFERROR(VLOOKUP(G43,Classifica!$C$2:$R$131,4,FALSE),"") | J43: =IFERROR(VLOOKUP(G43,Classifica!$C$2:$R$131,5,FALSE),"") | K43: =IFERROR(VLOOKUP(G43,Classifica!$C$2:$R$131,6,FALSE),"") | L43: =IFERROR(VLOOKUP(G43,Classifica!$C$2:$R$131,7,FALSE),"") | M43: =IFERROR(VLOOKUP(G43,Classifica!$C$2:$R$131,8,FALSE),"") | N43: =IFERROR(VLOOKUP(G43,Classifica!$C$2:$R$131,9,FALSE),"") | O43: =IFERROR(VLOOKUP(G43,Classifica!$C$2:$R$131,16,FALSE),"") | P43: =IFERROR(MID(INDEX(Classifica!M:M, MATCH(G43, Classifica!C:C, 0)), 1, 1), "") | Q43: =IFERROR(MID(INDEX(Classifica!M:M, MATCH(G43, Classifica!C:C, 0)), 3, 1), "") | R43: =IFERROR(MID(INDEX(Classifica!M:M, MATCH(G43, Classifica!C:C, 0)), 5, 1), "") | S43: =IFERROR(MID(INDEX(Classifica!M:M, MATCH(G43, Classifica!C:C, 0)), 7, 1), "") | T43: =IFERROR(MID(INDEX(Classifica!M:M, MATCH(G43, Classifica!C:C, 0)), 9, 1), "") | U43: =IFERROR(IF(P43="","",COUNTIF(P43:T43,"W")*20+COUNTIF(P43:T43,"D")*7),"") | W43: =COUNTIFS(Partite!AE:AE,1,Partite!Q:Q,Palinsesto!G43)+COUNTIFS(Partite!AE:AE,1,Partite!S:S,Palinsesto!G43) -> 0 | Y43: =INDEX(AD$4:AF$4, MATCH(MAX(AD43:AF43), AD43:AF43, 0)) -> 0-2 | Z43: =IFERROR(INT((LARGE(AD43:AF43,1)/SUM(H43:J43))*100),"") | AA43: =COUNTIFS(Partite!AL:AL,1,Partite!Q:Q,Palinsesto!G43)+COUNTIFS(Partite!AL:AL,1,Partite!S:S,Palinsesto!G43) -> 0 | AD43: =COUNTIFS(Partite!T:T,1,Partite!G:G,Palinsesto!G43)+COUNTIFS(Partite!W:W,1,Partite!I:I,Palinsesto!G43) -> 0 | AE43: =COUNTIFS(Partite!U:U,1,Partite!H:H,G43)+COUNTIFS(Partite!X:X,1,Partite!J:J,G43) -> 0 | AF43: =COUNTIFS(Partite!V:V,1,Partite!I:I,G43)+COUNTIFS(Partite!Y:Y,1,Partite!K:K,G43) -> 0
B45: =B42+1 -> 14 | C45: =VLOOKUP($B$2+B45,Partite!$A$1:$Z$2322,2,FALSE) -> Europa League | D45: =VLOOKUP($B$2+B45,Partite!$A$1:$Z$2322,3,FALSE) -> 0 | E45: =VALUE(TEXT(AC45, "GG/MM/AAAA")) -> 46226 | F45: =VLOOKUP($B$2+B45,Partite!$A$1:$Z$2322,6,FALSE) -> 20:00 | G45: =VLOOKUP($B$2+B45,Partite!$A$1:$Z$2322,7,FALSE) -> Twente nl | H45: =IFERROR(VLOOKUP(G45,Classifica!$C$2:$R$131,3,FALSE),"") | I45: =IFERROR(VLOOKUP(G45,Classifica!$C$2:$R$131,4,FALSE),"") | J45: =IFERROR(VLOOKUP(G45,Classifica!$C$2:$R$131,5,FALSE),"") | K45: =IFERROR(VLOOKUP(G45,Classifica!$C$2:$R$131,6,FALSE),"") | L45: =IFERROR(VLOOKUP(G45,Classifica!$C$2:$R$131,7,FALSE),"") | M45: =IFERROR(VLOOKUP(G45,Classifica!$C$2:$R$131,8,FALSE),"") | N45: =IFERROR(VLOOKUP(G45,Classifica!$C$2:$R$131,9,FALSE),"") | O45: =IFERROR(VLOOKUP(G45,Classifica!$C$2:$R$131,16,FALSE),"") | P45: =IFERROR(MID(INDEX(Classifica!M:M, MATCH(G45, Classifica!C:C, 0)), 1, 1), "") | Q45: =IFERROR(MID(INDEX(Classifica!M:M, MATCH(G45, Classifica!C:C, 0)), 3, 1), "") | R45: =IFERROR(MID(INDEX(Classifica!M:M, MATCH(G45, Classifica!C:C, 0)), 5, 1), "") | S45: =IFERROR(MID(INDEX(Classifica!M:M, MATCH(G45, Classifica!C:C, 0)), 7, 1), "") | T45: =IFERROR(MID(INDEX(Classifica!M:M, MATCH(G45, Classifica!C:C, 0)), 9, 1), "") | U45: =IFERROR(IF(P45="","",COUNTIF(P45:T45,"W")*20+COUNTIF(P45:T45,"D")*7),"") | V45: =IFERROR(ABS(U45-U46),"") | W45: =COUNTIFS(Partite!AE:AE,1,Partite!Q:Q,Palinsesto!G45)+COUNTIFS(Partite!AE:AE,1,Partite!S:S,Palinsesto!G45) -> 0 | X45: =IFERROR(AVERAGE(IFERROR(INT(W45/(SUM(H45:J45))*100),""),IFERROR(INT(W46/(SUM(H46:J46))*100),"")),"") | Y45: =INDEX(AD$4:AF$4, MATCH(MAX(AD45:AF45), AD45:AF45, 0)) -> 0-2 | Z45: =IFERROR(INT((LARGE(AD45:AF45,1)/SUM(H45:J45))*100),"") | AA45: =COUNTIFS(Partite!AL:AL,1,Partite!Q:Q,Palinsesto!G45)+COUNTIFS(Partite!AL:AL,1,Partite!S:S,Palinsesto!G45) -> 0 | AB45: =IFERROR(INT(AVERAGE(AA45/(SUM(H45:J45))*100,(AA46/(SUM(H46:J46))*100))),"") | AC45: =VLOOKUP($B$2+B45,Partite!$A$1:$E$2322,5,FALSE) -> 2026-07-23 | AD45: =COUNTIFS(Partite!T:T,1,Partite!G:G,Palinsesto!G45)+COUNTIFS(Partite!W:W,1,Partite!I:I,Palinsesto!G45) -> 0 | AE45: =COUNTIFS(Partite!U:U,1,Partite!H:H,G45)+COUNTIFS(Partite!X:X,1,Partite!J:J,G45) -> 0 | AF45: =COUNTIFS(Partite!V:V,1,Partite!I:I,G45)+COUNTIFS(Partite!Y:Y,1,Partite!K:K,G45) -> 0
G46: =VLOOKUP($B$2+B45,Partite!$A$1:$Z$2322,9,FALSE) -> hu Ferencváros | H46: =IFERROR(VLOOKUP(G46,Classifica!$C$2:$R$131,3,FALSE),"") | I46: =IFERROR(VLOOKUP(G46,Classifica!$C$2:$R$131,4,FALSE),"") | J46: =IFERROR(VLOOKUP(G46,Classifica!$C$2:$R$131,5,FALSE),"") | K46: =IFERROR(VLOOKUP(G46,Classifica!$C$2:$R$131,6,FALSE),"") | L46: =IFERROR(VLOOKUP(G46,Classifica!$C$2:$R$131,7,FALSE),"") | M46: =IFERROR(VLOOKUP(G46,Classifica!$C$2:$R$131,8,FALSE),"") | N46: =IFERROR(VLOOKUP(G46,Classifica!$C$2:$R$131,9,FALSE),"") | O46: =IFERROR(VLOOKUP(G46,Classifica!$C$2:$R$131,16,FALSE),"") | P46: =IFERROR(MID(INDEX(Classifica!M:M, MATCH(G46, Classifica!C:C, 0)), 1, 1), "") | Q46: =IFERROR(MID(INDEX(Classifica!M:M, MATCH(G46, Classifica!C:C, 0)), 3, 1), "") | R46: =IFERROR(MID(INDEX(Classifica!M:M, MATCH(G46, Classifica!C:C, 0)), 5, 1), "") | S46: =IFERROR(MID(INDEX(Classifica!M:M, MATCH(G46, Classifica!C:C, 0)), 7, 1), "") | T46: =IFERROR(MID(INDEX(Classifica!M:M, MATCH(G46, Classifica!C:C, 0)), 9, 1), "") | U46: =IFERROR(IF(P46="","",COUNTIF(P46:T46,"W")*20+COUNTIF(P46:T46,"D")*7),"") | W46: =COUNTIFS(Partite!AE:AE,1,Partite!Q:Q,Palinsesto!G46)+COUNTIFS(Partite!AE:AE,1,Partite!S:S,Palinsesto!G46) -> 0 | Y46: =INDEX(AD$4:AF$4, MATCH(MAX(AD46:AF46), AD46:AF46, 0)) -> 0-2 | Z46: =IFERROR(INT((LARGE(AD46:AF46,1)/SUM(H46:J46))*100),"") | AA46: =COUNTIFS(Partite!AL:AL,1,Partite!Q:Q,Palinsesto!G46)+COUNTIFS(Partite!AL:AL,1,Partite!S:S,Palinsesto!G46) -> 0 | AD46: =COUNTIFS(Partite!T:T,1,Partite!G:G,Palinsesto!G46)+COUNTIFS(Partite!W:W,1,Partite!I:I,Palinsesto!G46) -> 1 | AE46: =COUNTIFS(Partite!U:U,1,Partite!H:H,G46)+COUNTIFS(Partite!X:X,1,Partite!J:J,G46) -> 0 | AF46: =COUNTIFS(Partite!V:V,1,Partite!I:I,G46)+COUNTIFS(Partite!Y:Y,1,Partite!K:K,G46) -> 0
